Workbook
Name 삭제: 경동전체1!$A$2:$M$372

Sheet 경동샘플 양식3
A1: 받는분 | B1: 주소 | C1: 상세주소 | D1: 운송장번호 | E1: 고객사주문번호 | F1: 우편번호 | G1: 도착영업소 | H1: 전화번호 | I1: 기타전화번호 | J1: 선불후불 | K1: 품목명 | L1: 수량 | M1: 포장상태 | N1: 가로 | O1: 세로 | P1: 높이 | Q1: 무게 | R1: 개별단가(만원) | S1: 운임 | T1: 기타운임 | U1: 별도운임 | V1: 할증운임 | W1: 도서운임 | X1: 메모1 | Y1: 메모2 | Z1: 메모3 | AA1: =CONCATENATE(X1,",",Y1,",",Z1) -> 메모1,메모2,메모3
A2: 이주현★ | B2: 고양시 덕양구 원흥1로 31 (원흥동, 고양삼송엘에이치10단지아파트) 1004-502 | C2: ★파손주의★문 앞에 놓아주세요 | F2: 10562 | H2: 010-6412-7957 | I2: 010-6412-7957 | J2: 선불 | K2: ★증정★테이프20mx1 | L2: 1 | M2: 비닐 | N2: 1 | O2: 1 | P2: 1 | Q2: 1 | R2: 50 | S2: 19400 | T2: 100 | U2: 0 | V2: 0 | W2: 0 | X2: (140)17T퓨어아이8mx1 | AA2: =CONCATENATE(X2,",",Y2,",",Z2) -> (140)17T퓨어아이8mx1,,
A3: 전준하★ | B3: 화성시 병점3로 117 (병점동, 안화동마을주공9단지) 901동 1605호 | C3: ★파손주의★물품 잘 확인해서 보내주세요. 배송시 문자주시고 문앞에 놓아주세요. 감사합니다. | F3: 18405 | H3: 010-5153-1054 | I3: 010-5153-1054 | J3: 선불 | K3: ★증정★테이프20mx1 | L3: 1 | M3: 비닐 | N3: 1 | O3: 1 | P3: 1 | Q3: 1 | R3: 50 | S3: 19400 | T3: 100 | U3: 0 | V3: 0 | W3: 0 | X3: (140)17T퓨어아이8mx1 | AA3: =CONCATENATE(X3,",",Y3,",",Z3) -> (140)17T퓨어아이8mx1,,
A4: 나병준 | B4: 용인시 수지구 손곡로 82 (동천동, 수진마을써니벨리아파트) 106동 506호 | F4: 16823 | H4: 010-9174-1121 | I4: 010-9174-1121 | J4: 선불 | K4: 따사룸 | L4: 1 | M4: 비닐 | N4: 1 | O4: 1 | P4: 1 | Q4: 1 | R4: 50 | S4: 12700 | T4: 100 | U4: 0 | V4: 0 | W4: 0 | X4: 25T아이(50)x6 | AA4: =CONCATENATE(X4,",",Y4,",",Z4) -> 25T아이(50)x6,,
A5: 4-1나대남★ | B5: 서울 강북구 4.19로13길 9 (수유동, 우이블루빌) 402호 | C5: ★파손주의★ | F5: 01014 | H5: 010-8965-2389 | I5: 0502-3214-2132 | J5: 선불 | K5: 따사룸 | L5: 1 | M5: 비닐 | N5: 1 | O5: 1 | P5: 1 | Q5: 1 | R5: 50 | S5: 12700 | T5: 100 | U5: 0 | V5: 0 | W5: 0 | X5: (110)17T마블5.5mx1 | AA5: =CONCATENATE(X5,",",Y5,",",Z5) -> (110)17T마블5.5mx1,,
A6: 4-2나대남 | B6: 서울 강북구 4.19로13길 9 (수유동, 우이블루빌) 402호 | C6: 배송 전 미리 연락해 주세요 | F6: 01014 | H6: 010-8965-2389 | I6: 0502-3214-2132 | J6: 선불 | K6: ★증정★테이프20mx3 | L6: 1 | M6: 박스 | N6: 1 | O6: 1 | P6: 1 | Q6: 1 | R6: 50 | S6: 12100 | T6: 100 | U6: 0 | V6: 0 | W6: 0 | X6: (110)17T마블5mx1 | AA6: =CONCATENATE(X6,",",Y6,",",Z6) -> (110)17T마블5mx1,,
A7: 4-3나대남 | B7: 서울 강북구 4.19로13길 9 (수유동, 우이블루빌) 402호 | C7: 배송 전 미리 연락해 주세요 | F7: 01014 | H7: 010-8965-2389 | I7: 0502-3214-2132 | J7: 선불 | K7: ★판매★테이프20mx1 | L7: 1 | M7: 박스 | N7: 1 | O7: 1 | P7: 1 | Q7: 1 | R7: 50 | S7: 12100 | T7: 100 | U7: 0 | V7: 0 | W7: 0 | X7: (110)17T마블5mx1 | AA7: =CONCATENATE(X7,",",Y7,",",Z7) -> (110)17T마블5mx1,,
A8: 4-4나대남 | B8: 서울 강북구 4.19로13길 9 (수유동, 우이블루빌) 402호 | C8: 배송 전 미리 연락해 주세요 | F8: 01014 | H8: 010-8965-2389 | I8: 0502-3214-2132 | J8: 선불 | K8: 따사룸 | L8: 1 | M8: 박스 | N8: 1 | O8: 1 | P8: 1 | Q8: 1 | R8: 50 | S8: 13800 | T8: 100 | U8: 0 | V8: 0 | W8: 0 | X8: (120)17T마블3mx1 | Y8: (120)17T마블2mx1 | AA8: =CONCATENATE(X8,",",Y8,",",Z8) -> (120)17T마블3mx1,(120)17T마블2mx1,
A9: 최규철 | B9: 경북 상주시 이안면 양범안룡길 80 (이안면) 양범교회 | F9: 37107 | H9: 010-8823-9437 | I9: 010-8823-9437 | J9: 선불 | K9: 따사룸 | L9: 1 | M9: 박스 | N9: 1 | O9: 1 | P9: 1 | Q9: 1 | R9: 50 | S9: 8600 | T9: 100 | U9: 0 | V9: 0 | W9: 0 | X9: (140)6T그레이2mx1 | AA9: =CONCATENATE(X9,",",Y9,",",Z9) -> (140)6T그레이2mx1,,
A10: 한정우 | B10: 서울 강서구 양천로 177 (마곡동, 가양하수처리장직원아파트) 2동 206호 | F10: 07520 | H10: 010-9524-9234 | I10: 010-9524-9234 | J10: 선불 | K10: 따사룸 | L10: 1 | M10: 비닐 | N10: 1 | O10: 1 | P10: 1 | Q10: 1 | R10: 50 | S10: 6900 | T10: 100 | U10: 0 | V10: 0 | W10: 0 | X10: 플러스♥25T아이(100)x1 | AA10: =CONCATENATE(X10,",",Y10,",",Z10) -> 플러스♥25T아이(100)x1,,
A11: 2-1류춘렬 | B11: 대전 유성구 엑스포로 448 엑스포아파트 202동 1701호 | F11: 34049 | H11: 010-8736-8737 | I11: 010-8736-8737 | J11: 선불 | K11: ★증정★테이프20mx1 | L11: 1 | M11: 박스 | N11: 1 | O11: 1 | P11: 1 | Q11: 1 | R11: 50 | S11: 12100 | T11: 100 | U11: 0 | V11: 0 | W11: 0 | X11: (110)17T퓨어아이5mx1 | AA11: =CONCATENATE(X11,",",Y11,",",Z11) -> (110)17T퓨어아이5mx1,,
A12: 2-2류춘렬 | B12: 대전 유성구 엑스포로 448 엑스포아파트 202동 1701호 | F12: 34049 | H12: 010-8736-8737 | I12: 010-8736-8737 | J12: 선불 | K12: 따사룸 | L12: 1 | M12: 박스 | N12: 1 | O12: 1 | P12: 1 | Q12: 1 | R12: 50 | S12: 12100 | T12: 100 | U12: 0 | V12: 0 | W12: 0 | X12: (110)17T퓨어아이5mx1 | AA12: =CONCATENATE(X12,",",Y12,",",Z12) -> (110)17T퓨어아이5mx1,,
A13: 서혜린 | B13: 용인시 기흥구 기흥역로58번길 56 (구갈동, 기흥역 파크 푸르지오) 301동3302호 | F13: 17066 | H13: 010-3959-9166 | I13: 010-3959-9166 | J13: 선불 | K13: 따사룸 | L13: 1 | M13: 비닐 | N13: 1 | O13: 1 | P13: 1 | Q13: 1 | R13: 50 | S13: 6900 | T13: 100 | U13: 0 | V13: 0 | W13: 0 | X13: 25T아이(50)x2 | AA13: =CONCATENATE(X13,",",Y13,",",Z13) -> 25T아이(50)x2,,
A14: 최향 | B14: 의정부시 시민로 287 (신곡동) 이편한세상 신곡파크비스타 109동301호 | F14: 11748 | H14: 010-5550-1258 | I14: 010-5550-1258 | J14: 선불 | K14: 따사룸 | L14: 1 | M14: 박스 | N14: 1 | O14: 1 | P14: 1 | Q14: 1 | R14: 50 | S14: 8600 | T14: 100 | U14: 0 | V14: 0 | W14: 0 | X14: (120)17T그레이2mx1 | AA14: =CONCATENATE(X14,",",Y14,",",Z14) -> (120)17T그레이2mx1,,
A15: 2-1이규원 | B15: 구리시 원수택로32번길 60 (수택동, 성경아파트) 3동 402호 | C15: 부재시 문앞에 놔주세용 | F15: 11941 | H15: 010-8919-4157 | I15: 010-8919-4157 | J15: 선불 | K15: 따사룸 | L15: 1 | M15: 비닐 | N15: 1 | O15: 1 | P15: 1 | Q15: 1 | R15: 50 | S15: 10700 | T15: 100 | U15: 0 | V15: 0 | W15: 0 | X15: 25T아이(100)x5 | AA15: =CONCATENATE(X15,",",Y15,",",Z15) -> 25T아이(100)x5,,
A16: 2-2이규원 | B16: 구리시 원수택로32번길 60 (수택동, 성경아파트) 3동 402호 | C16: 부재시 문앞에 놔주세용 | F16: 11941 | H16: 010-8919-4157 | I16: 010-8919-4157 | J16: 선불 | K16: 따사룸 | L16: 1 | M16: 비닐 | N16: 1 | O16: 1 | P16: 1 | Q16: 1 | R16: 50 | S16: 10700 | T16: 100 | U16: 0 | V16: 0 | W16: 0 | X16: 25T아이(100)x3 | Y16: 25T아이(50)x2 | AA16: =CONCATENATE(X16,",",Y16,",",Z16) -> 25T아이(100)x3,25T아이(50)x2,
A17: 2-1김예찬 | B17: 대전 중구 계백로1615번길 34 (유천동, 현대아파트) 113동 1407호 | F17: 34899 | H17: 010-6886-3860 | I17: 010-6886-3860 | J17: 선불 | K17: 따사룸 | L17: 1 | M17: 비닐 | N17: 1 | O17: 1 | P17: 1 | Q17: 1 | R17: 50 | S17: 10700 | T17: 100 | U17: 0 | V17: 0 | W17: 0 | X17: 25T아이(100)x5 | AA17: =CONCATENATE(X17,",",Y17,",",Z17) -> 25T아이(100)x5,,
A18: 2-2김예찬 | B18: 대전 중구 계백로1615번길 34 (유천동, 현대아파트) 113동 1407호 | F18: 34899 | H18: 010-6886-3860 | I18: 010-6886-3860 | J18: 선불 | K18: 따사룸 | L18: 1 | M18: 비닐 | N18: 1 | O18: 1 | P18: 1 | Q18: 1 | R18: 50 | S18: 8600 | T18: 100 | U18: 0 | V18: 0 | W18: 0 | X18: 25T아이(100)x4 | AA18: =CONCATENATE(X18,",",Y18,",",Z18) -> 25T아이(100)x4,,
A19: 2-1최영미 | B19: 파주시 시청로 85 (아동동, 신안실크밸리2차 아파트) 206동303호 | F19: 10931 | H19: 010-5574-4480 | I19: 010-5574-4480 | J19: 선불 | K19: 따사룸 | L19: 1 | M19: 비닐 | N19: 1 | O19: 1 | P19: 1 | Q19: 1 | R19: 50 | S19: 8600 | T19: 100 | U19: 0 | V19: 0 | W19: 0 | X19: 25T아이(100)x4 | AA19: =CONCATENATE(X19,",",Y19,",",Z19) -> 25T아이(100)x4,,
A20: 2-2최영미 | B20: 파주시 시청로 85 (아동동, 신안실크밸리2차 아파트) 206동303호 | F20: 10931 | H20: 010-5574-4480 | I20: 010-5574-4480 | J20: 선불 | K20: 따사룸 | L20: 1 | M20: 비닐 | N20: 1 | O20: 1 | P20: 1 | Q20: 1 | R20: 50 | S20: 8600 | T20: 100 | U20: 0 | V20: 0 | W20: 0 | X20: 25T아이(100)x4 | AA20: =CONCATENATE(X20,",",Y20,",",Z20) -> 25T아이(100)x4,,
A21: 문경은 | B21: 서울 동작구 만양로 19 (노량진동, 상도신동아리버파크아파트) 707동 1405호 | F21: 06920 | H21: 010-3537-9446 | I21: 010-3537-9446 | J21: 선불 | K21: ★증정★테이프20mx1 | L21: 1 | M21: 박스 | N21: 1 | O21: 1 | P21: 1 | Q21: 1 | R21: 50 | S21: 15400 | T21: 100 | U21: 0 | V21: 0 | W21: 0 | X21: (140)12T퓨어아이5mx1 | AA21: =CONCATENATE(X21,",",Y21,",",Z21) -> (140)12T퓨어아이5mx1,,
A22: 이영진 | B22: 의정부시 가금로34번길 23 (가능동, 힐스테이트 녹양역) 103동2302호 | C22: 현관문 앞에다가 나둬두세요~ | F22: 11611 | H22: 010-3013-8148 | I22: 010-3013-8148 | J22: 선불 | K22: ★증정★테이프20mx1 | L22: 1 | M22: 박스 | N22: 1 | O22: 1 | P22: 1 | Q22: 1 | R22: 50 | S22: 15400 | T22: 100 | U22: 0 | V22: 0 | W22: 0 | X22: (140)9T도그프린트2.5mx1 | Y22: (110)9T도그프린트7.5mx1 | AA22: =CONCATENATE(X22,",",Y22,",",Z22) -> (140)9T도그프린트2.5mx1,(110)9T도그프린트7.5mx1,
A23: 권석영 | B23: 대구 북구 구리로 183-28 (학정동, 두산아파트) 201동 204호 | F23: 41408 | H23: 010-6208-9305 | I23: 010-6208-9305 | J23: 선불 | K23: 따사룸 | L23: 1 | M23: 비닐 | N23: 1 | O23: 1 | P23: 1 | Q23: 1 | R23: 50 | S23: 6900 | T23: 100 | U23: 0 | V23: 0 | W23: 0 | X23: 플러스♥25T아이(100)x1 | AA23: =CONCATENATE(X23,",",Y23,",",Z23) -> 플러스♥25T아이(100)x1,,
A24: 3-1고정일 | B24: 대전 대덕구 대화로 160 (대화동, 산업용재유통상가) 1동 207호 | F24: 34368 | H24: 010-5436-3781 | I24: 010-5436-3781 | J24: 선불 | K24: 따사룸 | L24: 1 | M24: 비닐 | N24: 1 | O24: 1 | P24: 1 | Q24: 1 | R24: 50 | S24: 12700 | T24: 100 | U24: 0 | V24: 0 | W24: 0 | X24: 25T아이(100)x6 | AA24: =CONCATENATE(X24,",",Y24,",",Z24) -> 25T아이(100)x6,,
A25: 3-2고정일 | B25: 대전 대덕구 대화로 160 (대화동, 산업용재유통상가) 1동 207호 | F25: 34368 | H25: 010-5436-3781 | I25: 010-5436-3781 | J25: 선불 | K25: 따사룸 | L25: 1 | M25: 비닐 | N25: 1 | O25: 1 | P25: 1 | Q25: 1 | R25: 50 | S25: 12700 | T25: 100 | U25: 0 | V25: 0 | W25: 0 | X25: 25T아이(100)x6 | AA25: =CONCATENATE(X25,",",Y25,",",Z25) -> 25T아이(100)x6,,
A26: 3-3고정일 | B26: 대전 대덕구 대화로 160 (대화동, 산업용재유통상가) 1동 207호 | F26: 34368 | H26: 010-5436-3781 | I26: 010-5436-3781 | J26: 선불 | K26: 따사룸 | L26: 1 | M26: 비닐 | N26: 1 | O26: 1 | P26: 1 | Q26: 1 | R26: 50 | S26: 8600 | T26: 100 | U26: 0 | V26: 0 | W26: 0 | X26: 25T블루(100)x2 | Y26: 25T핑크(100)x2 | AA26: =CONCATENATE(X26,",",Y26,",",Z26) -> 25T블루(100)x2,25T핑크(100)x2,
A27: 3-1지찬미 | B27: 강원 춘천시 백령로 215 (후평동, 춘천일성트루엘더퍼스트아파트) 107-1304 | F27: 24279 | H27: 010-4856-8776 | I27: 0502-3513-7025 | J27: 선불 | K27: 따사룸 | L27: 1 | M27: 비닐 | N27: 1 | O27: 1 | P27: 1 | Q27: 1 | R27: 50 | S27: 10700 | T27: 100 | U27: 0 | V27: 0 | W27: 0 | X27: 25T아이(100)x5 | AA27: =CONCATENATE(X27,",",Y27,",",Z27) -> 25T아이(100)x5,,
A28: 3-2지찬미 | B28: 강원 춘천시 백령로 215 (후평동, 춘천일성트루엘더퍼스트아파트) 107-1304 | F28: 24279 | H28: 010-4856-8776 | I28: 0502-3513-7025 | J28: 선불 | K28: 따사룸 | L28: 1 | M28: 비닐 | N28: 1 | O28: 1 | P28: 1 | Q28: 1 | R28: 50 | S28: 10700 | T28: 100 | U28: 0 | V28: 0 | W28: 0 | X28: 25T아이(100)x5 | AA28: =CONCATENATE(X28,",",Y28,",",Z28) -> 25T아이(100)x5,,
A29: 3-3지찬미 | B29: 강원 춘천시 백령로 215 (후평동, 춘천일성트루엘더퍼스트아파트) 107-1304 | F29: 24279 | H29: 010-4856-8776 | I29: 0502-3513-7025 | J29: 선불 | K29: 따사룸 | L29: 1 | M29: 비닐 | N29: 1 | O29: 1 | P29: 1 | Q29: 1 | R29: 50 | S29: 10700 | T29: 100 | U29: 0 | V29: 0 | W29: 0 | X29: 25T아이(100)x5 | AA29: =CONCATENATE(X29,",",Y29,",",Z29) -> 25T아이(100)x5,,
A30: 정다훈 | B30: 용인시 수지구 용구대로 2720 (죽전동, 현암마을동성2차아파트) 203동 1302호 | C30: 배송 전 미리 연락해 주세요 | F30: 16868 | H30: 010-9490-8874 | I30: 010-9490-8874 | J30: 선불 | K30: 따사룸 | L30: 1 | M30: 비닐 | N30: 1 | O30: 1 | P30: 1 | Q30: 1 | R30: 50 | S30: 10700 | T30: 100 | U30: 0 | V30: 0 | W30: 0 | X30: 40T아이(100)x3 | AA30: =CONCATENATE(X30,",",Y30,",",Z30) -> 40T아이(100)x3,,
A31: 3-1이슬 | B31: 여주시 산북면 상품로 72 (산북면) 1층 102호 | F31: 12603 | H31: 010-5424-9068 | I31: 010-5424-9068 | J31: 선불 | K31: 따사룸 | L31: 1 | M31: 비닐 | N31: 1 | O31: 1 | P31: 1 | Q31: 1 | R31: 50 | S31: 12700 | T31: 100 | U31: 0 | V31: 0 | W31: 0 | X31: 25T아이(100)x6 | AA31: =CONCATENATE(X31,",",Y31,",",Z31) -> 25T아이(100)x6,,
A32: 3-2이슬 | B32: 여주시 산북면 상품로 72 (산북면) 1층 102호 | F32: 12603 | H32: 010-5424-9068 | I32: 010-5424-9068 | J32: 선불 | K32: 따사룸 | L32: 1 | M32: 비닐 | N32: 1 | O32: 1 | P32: 1 | Q32: 1 | R32: 50 | S32: 12700 | T32: 100 | U32: 0 | V32: 0 | W32: 0 | X32: 25T아이(100)x6 | AA32: =CONCATENATE(X32,",",Y32,",",Z32) -> 25T아이(100)x6,,
A33: 3-3이슬 | B33: 여주시 산북면 상품로 72 (산북면) 1층 102호 | F33: 12603 | H33: 010-5424-9068 | I33: 010-5424-9068 | J33: 선불 | K33: 따사룸 | L33: 1 | M33: 비닐 | N33: 1 | O33: 1 | P33: 1 | Q33: 1 | R33: 50 | S33: 12700 | T33: 100 | U33: 0 | V33: 0 | W33: 0 | X33: 25T아이(100)x6 | AA33: =CONCATENATE(X33,",",Y33,",",Z33) -> 25T아이(100)x6,,
A34: 3-1김영국 | B34: 전북도 전주시 덕진구 세병로 130 (송천동2가, 에코시티 데시앙 네스트) 802동1403호 | F34: 55150 | H34: 010-9080-1385 | I34: 010-9080-1385 | J34: 선불 | K34: ★증정★테이프20mx3 | L34: 1 | M34: 박스 | N34: 1 | O34: 1 | P34: 1 | Q34: 1 | R34: 50 | S34: 15400 | T34: 100 | U34: 0 | V34: 0 | W34: 0 | X34: (140)17T퓨어아이4mx1 | AA34: =CONCATENATE(X34,",",Y34,",",Z34) -> (140)17T퓨어아이4mx1,,
A35: 3-2김영국 | B35: 전북도 전주시 덕진구 세병로 130 (송천동2가, 에코시티 데시앙 네스트) 802동1403호 | F35: 55150 | H35: 010-9080-1385 | I35: 010-9080-1385 | J35: 선불 | K35: 따사룸 | L35: 1 | M35: 박스 | N35: 1 | O35: 1 | P35: 1 | Q35: 1 | R35: 50 | S35: 15400 | T35: 100 | U35: 0 | V35: 0 | W35: 0 | X35: (140)17T퓨어아이2.5mx1 | AA35: =CONCATENATE(X35,",",Y35,",",Z35) -> (140)17T퓨어아이2.5mx1,,
A36: 3-3김영국★ | B36: 전북도 전주시 덕진구 세병로 130 (송천동2가, 에코시티 데시앙 네스트) 802동1403호 | C36: ★파손주의★ | F36: 55150 | H36: 010-9080-1385 | I36: 010-9080-1385 | J36: 선불 | K36: 따사룸 | L36: 1 | M36: 비닐 | N36: 1 | O36: 1 | P36: 1 | Q36: 1 | R36: 50 | S36: 16700 | T36: 100 | U36: 0 | V36: 0 | W36: 0 | X36: (120)17T퓨어아이8mx1 | AA36: =CONCATENATE(X36,",",Y36,",",Z36) -> (120)17T퓨어아이8mx1,,
A37: 김득봉 | B37: 전남 해남군 화원면 금평길 54 (화원면, 궁전빌라) 404호 | F37: 59002 | H37: 010-4686-0482 | I37: 010-4686-0482 | J37: 선불 | K37: 따사룸 | L37: 1 | M37: 비닐 | N37: 1 | O37: 1 | P37: 1 | Q37: 1 | R37: 50 | S37: 6900 | T37: 100 | U37: 0 | V37: 0 | W37: 0 | X37: 25T그레이(100)x3 | AA37: =CONCATENATE(X37,",",Y37,",",Z37) -> 25T그레이(100)x3,,
A38: 2-1김규동 | B38: 부산 금정구 중앙대로1685번길 24 (부곡동, 경남한신아파트) 101동 1201호 | C38: 문앞에 놔주세요. | F38: 46277 | H38: 010-7220-3846 | I38: 010-7220-3846 | J38: 선불 | K38: 따사룸 | L38: 1 | M38: 박스 | N38: 1 | O38: 1 | P38: 1 | Q38: 1 | R38: 50 | S38: 13800 | T38: 100 | U38: 0 | V38: 0 | W38: 0 | X38: (120)22T퓨어아이2.5mx1 | AA38: =CONCATENATE(X38,",",Y38,",",Z38) -> (120)22T퓨어아이2.5mx1,,
A39: 2-2김규동 | B39: 부산 금정구 중앙대로1685번길 24 (부곡동, 경남한신아파트) 101동 1201호 | C39: 문앞에 놔주세요. | F39: 46277 | H39: 010-7220-3846 | I39: 010-7220-3846 | J39: 선불 | K39: ★판매★테이프20mx1 | L39: 1 | M39: 박스 | N39: 1 | O39: 1 | P39: 1 | Q39: 1 | R39: 50 | S39: 12100 | T39: 100 | U39: 0 | V39: 0 | W39: 0 | X39: (110)22T퓨어아이2.5mx1 | AA39: =CONCATENATE(X39,",",Y39,",",Z39) -> (110)22T퓨어아이2.5mx1,,
A40: 5-1이좌훈 | B40: 평택시 신장로 55 (신장동) 사서함 309-25호 (공군 1887부대) | F40: 17759 | H40: 010-5023-9290 | I40: 010-5023-9290 | J40: 선불 | K40: 따사룸 | L40: 1 | M40: 비닐 | N40: 1 | O40: 1 | P40: 1 | Q40: 1 | R40: 50 | S40: 12700 | T40: 100 | U40: 0 | V40: 0 | W40: 0 | X40: 플러스♥25T크림그레이(50)x6 | AA40: =CONCATENATE(X40,",",Y40,",",Z40) -> 플러스♥25T크림그레이(50)x6,,
...

Sheet 경동발주서 양식2
A1: 받는분 | B1: 주소 | C1: 상세주소 | D1: 운송장번호 | E1: 고객사주문번호 | F1: 우편번호 | G1: 도착영업소 | H1: 전화번호 | I1: 기타전화번호 | J1: 선불후불 | K1: 품목명 | L1: 수량 | M1: 포장상태 | N1: 가로 | O1: 세로 | P1: 높이 | Q1: 무게 | R1: 개별단가(만원) | S1: 운임 | T1: 기타운임 | U1: 별도운임 | V1: 할증운임 | W1: 도서운임 | X1: 메모1
A2: =경동전체1!A2 -> 이주현★ | B2: =SUBSTITUTE(SUBSTITUTE(SUBSTITUTE(SUBSTITUTE(SUBSTITUTE(SUBSTITUTE(SUBSTITUTE(SUBSTITUTE(SUBSTITUTE(SUBSTITUTE(SUBSTITUTE(SUBSTITUTE(SUBSTITUTE(경동전체1!K2,"특별시",""),"광역시",""),"직할시",""),"경기도",""),"충청북도","충북"),"충청남도","충남"),"경상북도","경북"),"경상남도","경남"),"강원도","강원"),"특별자치",""),"전라남도","전남"),"전라북도","전북"),"아파트,","") -> 고양시 덕양구 원흥1로 31 (원흥동, 고양삼송엘에이치10단지아파트) 1004-502 | C2: =경동전체1!E2 -> ★파손주의★문 앞에 놓아주세요 | F2: =경동전체1!J2 -> 10562 | H2: =경동전체1!H2 -> 010-6412-7957 | I2: =경동전체1!I2&"" -> 010-6412-7957 | J2: 선불 | K2: =IF(LEFT(경동전체1!G2,1)="","따사룸",경동전체1!G2) -> ★증정★테이프20mx1 | L2: ="1" -> 1 | M2: =IF(LEFT(경동전체1!D2,1)="2","비닐",IF(LEFT(경동전체1!O2,1)="박","박스","비닐")) -> 비닐 | N2: 1 | O2: 1 | P2: 1 | Q2: 1 | R2: ="50" -> 50 | S2: =경동전체1!B2 -> 19400 | T2: ="100" -> 100 | U2: ="0" -> 0 | V2: 0 | W2: 0 | X2: =SUBSTITUTE(SUBSTITUTE(SUBSTITUTE(SUBSTITUTE(SUBSTITUTE(SUBSTITUTE(SUBSTITUTE(SUBSTITUTE(SUBSTITUTE(SUBSTITUTE(SUBSTITUTE(SUBSTITUTE(SUBSTITUTE(경동전체1!D2,"마블아이보리","마블"),"100x100(1장)","(100)"),"50x50(4장)","(50)"),"실리콘테이프","테이프"),"★증정품★","★증★"),"(퍼즐)",""),"mm",""),"폭",""),"딜라이트우드","우드"),"그레캔버스","캔버스"),"소프트그레이","그레이"),"(퍼)",""),"아이보리","아이") -> (140)17T퓨어아이8mx1
A3: =경동전체1!A3 -> 전준하★ | B3: =SUBSTITUTE(SUBSTITUTE(SUBSTITUTE(SUBSTITUTE(SUBSTITUTE(SUBSTITUTE(SUBSTITUTE(SUBSTITUTE(SUBSTITUTE(SUBSTITUTE(SUBSTITUTE(SUBSTITUTE(SUBSTITUTE(경동전체1!K3,"특별시",""),"광역시",""),"직할시",""),"경기도",""),"충청북도","충북"),"충청남도","충남"),"경상북도","경북"),"경상남도","경남"),"강원도","강원"),"특별자치",""),"전라남도","전남"),"전라북도","전북"),"아파트,","") -> 화성시 병점3로 117 (병점동, 안화동마을주공9단지) 901동 1605호 | C3: =경동전체1!E3 -> ★파손주의★물품 잘 확인해서 보내주세요. 배송시 문자주시고 문앞에 놓아주세요. 감사합니다. | F3: =경동전체1!J3 -> 18405 | H3: =경동전체1!H3 -> 010-5153-1054 | I3: =경동전체1!I3&"" -> 010-5153-1054 | J3: 선불 | K3: =IF(LEFT(경동전체1!G3,1)="","따사룸",경동전체1!G3) -> ★증정★테이프20mx1 | L3: ="1" -> 1 | M3: =IF(LEFT(경동전체1!D3,1)="2","비닐",IF(LEFT(경동전체1!O3,1)="박","박스","비닐")) -> 비닐 | N3: 1 | O3: 1 | P3: 1 | Q3: 1 | R3: ="50" -> 50 | S3: =경동전체1!B3 -> 19400 | T3: ="100" -> 100 | U3: ="0" -> 0 | V3: 0 | W3: 0 | X3: =SUBSTITUTE(SUBSTITUTE(SUBSTITUTE(SUBSTITUTE(SUBSTITUTE(SUBSTITUTE(SUBSTITUTE(SUBSTITUTE(SUBSTITUTE(SUBSTITUTE(SUBSTITUTE(SUBSTITUTE(SUBSTITUTE(경동전체1!D3,"마블아이보리","마블"),"100x100(1장)","(100)"),"50x50(4장)","(50)"),"실리콘테이프","테이프"),"★증정품★","★증★"),"(퍼즐)",""),"mm",""),"폭",""),"딜라이트우드","우드"),"그레캔버스","캔버스"),"소프트그레이","그레이"),"(퍼)",""),"아이보리","아이") -> (140)17T퓨어아이8mx1
A4: =경동전체1!A4 -> 나병준 | B4: =SUBSTITUTE(SUBSTITUTE(SUBSTITUTE(SUBSTITUTE(SUBSTITUTE(SUBSTITUTE(SUBSTITUTE(SUBSTITUTE(SUBSTITUTE(SUBSTITUTE(SUBSTITUTE(SUBSTITUTE(SUBSTITUTE(경동전체1!K4,"특별시",""),"광역시",""),"직할시",""),"경기도",""),"충청북도","충북"),"충청남도","충남"),"경상북도","경북"),"경상남도","경남"),"강원도","강원"),"특별자치",""),"전라남도","전남"),"전라북도","전북"),"아파트,","") -> 용인시 수지구 손곡로 82 (동천동, 수진마을써니벨리아파트) 106동 506호 | C4: =경동전체1!E4 -> 0 | F4: =경동전체1!J4 -> 16823 | H4: =경동전체1!H4 -> 010-9174-1121 | I4: =경동전체1!I4&"" -> 010-9174-1121 | J4: 선불 | K4: =IF(LEFT(경동전체1!G4,1)="","따사룸",경동전체1!G4) -> 따사룸 | L4: ="1" -> 1 | M4: =IF(LEFT(경동전체1!D4,1)="2","비닐",IF(LEFT(경동전체1!O4,1)="박","박스","비닐")) -> 비닐 | N4: 1 | O4: 1 | P4: 1 | Q4: 1 | R4: ="50" -> 50 | S4: =경동전체1!B4 -> 12700 | T4: ="100" -> 100 | U4: ="0" -> 0 | V4: 0 | W4: 0 | X4: =SUBSTITUTE(SUBSTITUTE(SUBSTITUTE(SUBSTITUTE(SUBSTITUTE(SUBSTITUTE(SUBSTITUTE(SUBSTITUTE(SUBSTITUTE(SUBSTITUTE(SUBSTITUTE(SUBSTITUTE(SUBSTITUTE(경동전체1!D4,"마블아이보리","마블"),"100x100(1장)","(100)"),"50x50(4장)","(50)"),"실리콘테이프","테이프"),"★증정품★","★증★"),"(퍼즐)",""),"mm",""),"폭",""),"딜라이트우드","우드"),"그레캔버스","캔버스"),"소프트그레이","그레이"),"(퍼)",""),"아이보리","아이") -> 25T아이(50)x6
A5: =경동전체1!A5 -> 4-3나대남 | B5: =SUBSTITUTE(SUBSTITUTE(SUBSTITUTE(SUBSTITUTE(SUBSTITUTE(SUBSTITUTE(SUBSTITUTE(SUBSTITUTE(SUBSTITUTE(SUBSTITUTE(SUBSTITUTE(SUBSTITUTE(SUBSTITUTE(경동전체1!K5,"특별시",""),"광역시",""),"직할시",""),"경기도",""),"충청북도","충북"),"충청남도","충남"),"경상북도","경북"),"경상남도","경남"),"강원도","강원"),"특별자치",""),"전라남도","전남"),"전라북도","전북"),"아파트,","") -> 서울 강북구 4.19로13길 9 (수유동, 우이블루빌) 402호 | C5: =경동전체1!E5 -> 배송 전 미리 연락해 주세요 | F5: =경동전체1!J5 -> 01014 | H5: =경동전체1!H5 -> 010-8965-2389 | I5: =경동전체1!I5&"" -> 0502-3214-2132 | J5: 선불 | K5: =IF(LEFT(경동전체1!G5,1)="","따사룸",경동전체1!G5) -> 따사룸 | L5: ="1" -> 1 | M5: =IF(LEFT(경동전체1!D5,1)="2","비닐",IF(LEFT(경동전체1!O5,1)="박","박스","비닐")) -> 비닐 | N5: 1 | O5: 1 | P5: 1 | Q5: 1 | R5: ="50" -> 50 | S5: =경동전체1!B5 -> 0 | T5: ="100" -> 100 | U5: ="0" -> 0 | V5: 0 | W5: 0 | X5: =SUBSTITUTE(SUBSTITUTE(SUBSTITUTE(SUBSTITUTE(SUBSTITUTE(SUBSTITUTE(SUBSTITUTE(SUBSTITUTE(SUBSTITUTE(SUBSTITUTE(SUBSTITUTE(SUBSTITUTE(SUBSTITUTE(경동전체1!D5,"마블아이보리","마블"),"100x100(1장)","(100)"),"50x50(4장)","(50)"),"실리콘테이프","테이프"),"★증정품★","★증★"),"(퍼즐)",""),"mm",""),"폭",""),"딜라이트우드","우드"),"그레캔버스","캔버스"),"소프트그레이","그레이"),"(퍼)",""),"아이보리","아이") -> ★판매★테이프20mx1
A6: =경동전체1!A6 -> 4-1나대남★ | B6: =SUBSTITUTE(SUBSTITUTE(SUBSTITUTE(SUBSTITUTE(SUBSTITUTE(SUBSTITUTE(SUBSTITUTE(SUBSTITUTE(SUBSTITUTE(SUBSTITUTE(SUBSTITUTE(SUBSTITUTE(SUBSTITUTE(경동전체1!K6,"특별시",""),"광역시",""),"직할시",""),"경기도",""),"충청북도","충북"),"충청남도","충남"),"경상북도","경북"),"경상남도","경남"),"강원도","강원"),"특별자치",""),"전라남도","전남"),"전라북도","전북"),"아파트,","") -> 서울 강북구 4.19로13길 9 (수유동, 우이블루빌) 402호 | C6: =경동전체1!E6 -> ★파손주의★ | F6: =경동전체1!J6 -> 01014 | H6: =경동전체1!H6 -> 010-8965-2389 | I6: =경동전체1!I6&"" -> 0502-3214-2132 | J6: 선불 | K6: =IF(LEFT(경동전체1!G6,1)="","따사룸",경동전체1!G6) -> 따사룸 | L6: ="1" -> 1 | M6: =IF(LEFT(경동전체1!D6,1)="2","비닐",IF(LEFT(경동전체1!O6,1)="박","박스","비닐")) -> 비닐 | N6: 1 | O6: 1 | P6: 1 | Q6: 1 | R6: ="50" -> 50 | S6: =경동전체1!B6 -> 12700 | T6: ="100" -> 100 | U6: ="0" -> 0 | V6: 0 | W6: 0 | X6: =SUBSTITUTE(SUBSTITUTE(SUBSTITUTE(SUBSTITUTE(SUBSTITUTE(SUBSTITUTE(SUBSTITUTE(SUBSTITUTE(SUBSTITUTE(SUBSTITUTE(SUBSTITUTE(SUBSTITUTE(SUBSTITUTE(경동전체1!D6,"마블아이보리","마블"),"100x100(1장)","(100)"),"50x50(4장)","(50)"),"실리콘테이프","테이프"),"★증정품★","★증★"),"(퍼즐)",""),"mm",""),"폭",""),"딜라이트우드","우드"),"그레캔버스","캔버스"),"소프트그레이","그레이"),"(퍼)",""),"아이보리","아이") -> (110)17T마블5.5mx1
A7: =경동전체1!A7 -> 4-2나대남 | B7: =SUBSTITUTE(SUBSTITUTE(SUBSTITUTE(SUBSTITUTE(SUBSTITUTE(SUBSTITUTE(SUBSTITUTE(SUBSTITUTE(SUBSTITUTE(SUBSTITUTE(SUBSTITUTE(SUBSTITUTE(SUBSTITUTE(경동전체1!K7,"특별시",""),"광역시",""),"직할시",""),"경기도",""),"충청북도","충북"),"충청남도","충남"),"경상북도","경북"),"경상남도","경남"),"강원도","강원"),"특별자치",""),"전라남도","전남"),"전라북도","전북"),"아파트,","") -> 서울 강북구 4.19로13길 9 (수유동, 우이블루빌) 402호 | C7: =경동전체1!E7 -> 배송 전 미리 연락해 주세요 | F7: =경동전체1!J7 -> 01014 | H7: =경동전체1!H7 -> 010-8965-2389 | I7: =경동전체1!I7&"" -> 0502-3214-2132 | J7: 선불 | K7: =IF(LEFT(경동전체1!G7,1)="","따사룸",경동전체1!G7) -> ★증정★테이프20mx3 | L7: ="1" -> 1 | M7: =IF(LEFT(경동전체1!D7,1)="2","비닐",IF(LEFT(경동전체1!O7,1)="박","박스","비닐")) -> 박스 | N7: 1 | O7: 1 | P7: 1 | Q7: 1 | R7: ="50" -> 50 | S7: =경동전체1!B7 -> 12100 | T7: ="100" -> 100 | U7: ="0" -> 0 | V7: 0 | W7: 0 | X7: =SUBSTITUTE(SUBSTITUTE(SUBSTITUTE(SUBSTITUTE(SUBSTITUTE(SUBSTITUTE(SUBSTITUTE(SUBSTITUTE(SUBSTITUTE(SUBSTITUTE(SUBSTITUTE(SUBSTITUTE(SUBSTITUTE(경동전체1!D7,"마블아이보리","마블"),"100x100(1장)","(100)"),"50x50(4장)","(50)"),"실리콘테이프","테이프"),"★증정품★","★증★"),"(퍼즐)",""),"mm",""),"폭",""),"딜라이트우드","우드"),"그레캔버스","캔버스"),"소프트그레이","그레이"),"(퍼)",""),"아이보리","아이") -> (110)17T마블5mx1
A8: =경동전체1!A8 -> 4-3나대남 | B8: =SUBSTITUTE(SUBSTITUTE(SUBSTITUTE(SUBSTITUTE(SUBSTITUTE(SUBSTITUTE(SUBSTITUTE(SUBSTITUTE(SUBSTITUTE(SUBSTITUTE(SUBSTITUTE(SUBSTITUTE(SUBSTITUTE(경동전체1!K8,"특별시",""),"광역시",""),"직할시",""),"경기도",""),"충청북도","충북"),"충청남도","충남"),"경상북도","경북"),"경상남도","경남"),"강원도","강원"),"특별자치",""),"전라남도","전남"),"전라북도","전북"),"아파트,","") -> 서울 강북구 4.19로13길 9 (수유동, 우이블루빌) 402호 | C8: =경동전체1!E8 -> 배송 전 미리 연락해 주세요 | F8: =경동전체1!J8 -> 01014 | H8: =경동전체1!H8 -> 010-8965-2389 | I8: =경동전체1!I8&"" -> 0502-3214-2132 | J8: 선불 | K8: =IF(LEFT(경동전체1!G8,1)="","따사룸",경동전체1!G8) -> 따사룸 | L8: ="1" -> 1 | M8: =IF(LEFT(경동전체1!D8,1)="2","비닐",IF(LEFT(경동전체1!O8,1)="박","박스","비닐")) -> 박스 | N8: 1 | O8: 1 | P8: 1 | Q8: 1 | R8: ="50" -> 50 | S8: =경동전체1!B8 -> 12100 | T8: ="100" -> 100 | U8: ="0" -> 0 | V8: 0 | W8: 0 | X8: =SUBSTITUTE(SUBSTITUTE(SUBSTITUTE(SUBSTITUTE(SUBSTITUTE(SUBSTITUTE(SUBSTITUTE(SUBSTITUTE(SUBSTITUTE(SUBSTITUTE(SUBSTITUTE(SUBSTITUTE(SUBSTITUTE(경동전체1!D8,"마블아이보리","마블"),"100x100(1장)","(100)"),"50x50(4장)","(50)"),"실리콘테이프","테이프"),"★증정품★","★증★"),"(퍼즐)",""),"mm",""),"폭",""),"딜라이트우드","우드"),"그레캔버스","캔버스"),"소프트그레이","그레이"),"(퍼)",""),"아이보리","아이") -> (110)17T마블5mx1
A9: =경동전체1!A9 -> 4-4나대남 | B9: =SUBSTITUTE(SUBSTITUTE(SUBSTITUTE(SUBSTITUTE(SUBSTITUTE(SUBSTITUTE(SUBSTITUTE(SUBSTITUTE(SUBSTITUTE(SUBSTITUTE(SUBSTITUTE(SUBSTITUTE(SUBSTITUTE(경동전체1!K9,"특별시",""),"광역시",""),"직할시",""),"경기도",""),"충청북도","충북"),"충청남도","충남"),"경상북도","경북"),"경상남도","경남"),"강원도","강원"),"특별자치",""),"전라남도","전남"),"전라북도","전북"),"아파트,","") -> 서울 강북구 4.19로13길 9 (수유동, 우이블루빌) 402호 | C9: =경동전체1!E9 -> 배송 전 미리 연락해 주세요 | F9: =경동전체1!J9 -> 01014 | H9: =경동전체1!H9 -> 010-8965-2389 | I9: =경동전체1!I9&"" -> 0502-3214-2132 | J9: 선불 | K9: =IF(LEFT(경동전체1!G9,1)="","따사룸",경동전체1!G9) -> 따사룸 | L9: ="1" -> 1 | M9: =IF(LEFT(경동전체1!D9,1)="2","비닐",IF(LEFT(경동전체1!O9,1)="박","박스","비닐")) -> 박스 | N9: 1 | O9: 1 | P9: 1 | Q9: 1 | R9: ="50" -> 50 | S9: =경동전체1!B9 -> 13800 | T9: ="100" -> 100 | U9: ="0" -> 0 | V9: 0 | W9: 0 | X9: =SUBSTITUTE(SUBSTITUTE(SUBSTITUTE(SUBSTITUTE(SUBSTITUTE(SUBSTITUTE(SUBSTITUTE(SUBSTITUTE(SUBSTITUTE(SUBSTITUTE(SUBSTITUTE(SUBSTITUTE(SUBSTITUTE(경동전체1!D9,"마블아이보리","마블"),"100x100(1장)","(100)"),"50x50(4장)","(50)"),"실리콘테이프","테이프"),"★증정품★","★증★"),"(퍼즐)",""),"mm",""),"폭",""),"딜라이트우드","우드"),"그레캔버스","캔버스"),"소프트그레이","그레이"),"(퍼)",""),"아이보리","아이") -> (120)17T마블3mx1
A10: =경동전체1!A10 -> 4-4나대남 | B10: =SUBSTITUTE(SUBSTITUTE(SUBSTITUTE(SUBSTITUTE(SUBSTITUTE(SUBSTITUTE(SUBSTITUTE(SUBSTITUTE(SUBSTITUTE(SUBSTITUTE(SUBSTITUTE(SUBSTITUTE(SUBSTITUTE(경동전체1!K10,"특별시",""),"광역시",""),"직할시",""),"경기도",""),"충청북도","충북"),"충청남도","충남"),"경상북도","경북"),"경상남도","경남"),"강원도","강원"),"특별자치",""),"전라남도","전남"),"전라북도","전북"),"아파트,","") -> 서울 강북구 4.19로13길 9 (수유동, 우이블루빌) 402호 | C10: =경동전체1!E10 -> 배송 전 미리 연락해 주세요 | F10: =경동전체1!J10 -> 01014 | H10: =경동전체1!H10 -> 010-8965-2389 | I10: =경동전체1!I10&"" -> 0502-3214-2132 | J10: 선불 | K10: =IF(LEFT(경동전체1!G10,1)="","따사룸",경동전체1!G10) -> 따사룸 | L10: ="1" -> 1 | M10: =IF(LEFT(경동전체1!D10,1)="2","비닐",IF(LEFT(경동전체1!O10,1)="박","박스","비닐")) -> 비닐 | N10: 1 | O10: 1 | P10: 1 | Q10: 1 | R10: ="50" -> 50 | S10: =경동전체1!B10 -> 0 | T10: ="100" -> 100 | U10: ="0" -> 0 | V10: 0 | W10: 0 | X10: =SUBSTITUTE(SUBSTITUTE(SUBSTITUTE(SUBSTITUTE(SUBSTITUTE(SUBSTITUTE(SUBSTITUTE(SUBSTITUTE(SUBSTITUTE(SUBSTITUTE(SUBSTITUTE(SUBSTITUTE(SUBSTITUTE(경동전체1!D10,"마블아이보리","마블"),"100x100(1장)","(100)"),"50x50(4장)","(50)"),"실리콘테이프","테이프"),"★증정품★","★증★"),"(퍼즐)",""),"mm",""),"폭",""),"딜라이트우드","우드"),"그레캔버스","캔버스"),"소프트그레이","그레이"),"(퍼)",""),"아이보리","아이") -> (120)17T마블2mx1
A11: =경동전체1!A11 -> 최규철 | B11: =SUBSTITUTE(SUBSTITUTE(SUBSTITUTE(SUBSTITUTE(SUBSTITUTE(SUBSTITUTE(SUBSTITUTE(SUBSTITUTE(SUBSTITUTE(SUBSTITUTE(SUBSTITUTE(SUBSTITUTE(SUBSTITUTE(경동전체1!K11,"특별시",""),"광역시",""),"직할시",""),"경기도",""),"충청북도","충북"),"충청남도","충남"),"경상북도","경북"),"경상남도","경남"),"강원도","강원"),"특별자치",""),"전라남도","전남"),"전라북도","전북"),"아파트,","") -> 경북 상주시 이안면 양범안룡길 80 (이안면) 양범교회 | C11: =경동전체1!E11 -> 0 | F11: =경동전체1!J11 -> 37107 | H11: =경동전체1!H11 -> 010-8823-9437 | I11: =경동전체1!I11&"" -> 010-8823-9437 | J11: 선불 | K11: =IF(LEFT(경동전체1!G11,1)="","따사룸",경동전체1!G11) -> 따사룸 | L11: ="1" -> 1 | M11: =IF(LEFT(경동전체1!D11,1)="2","비닐",IF(LEFT(경동전체1!O11,1)="박","박스","비닐")) -> 박스 | N11: 1 | O11: 1 | P11: 1 | Q11: 1 | R11: ="50" -> 50 | S11: =경동전체1!B11 -> 8600 | T11: ="100" -> 100 | U11: ="0" -> 0 | V11: 0 | W11: 0 | X11: =SUBSTITUTE(SUBSTITUTE(SUBSTITUTE(SUBSTITUTE(SUBSTITUTE(SUBSTITUTE(SUBSTITUTE(SUBSTITUTE(SUBSTITUTE(SUBSTITUTE(SUBSTITUTE(SUBSTITUTE(SUBSTITUTE(경동전체1!D11,"마블아이보리","마블"),"100x100(1장)","(100)"),"50x50(4장)","(50)"),"실리콘테이프","테이프"),"★증정품★","★증★"),"(퍼즐)",""),"mm",""),"폭",""),"딜라이트우드","우드"),"그레캔버스","캔버스"),"소프트그레이","그레이"),"(퍼)",""),"아이보리","아이") -> (140)6T그레이2mx1
A12: =경동전체1!A12 -> 한정우 | B12: =SUBSTITUTE(SUBSTITUTE(SUBSTITUTE(SUBSTITUTE(SUBSTITUTE(SUBSTITUTE(SUBSTITUTE(SUBSTITUTE(SUBSTITUTE(SUBSTITUTE(SUBSTITUTE(SUBSTITUTE(SUBSTITUTE(경동전체1!K12,"특별시",""),"광역시",""),"직할시",""),"경기도",""),"충청북도","충북"),"충청남도","충남"),"경상북도","경북"),"경상남도","경남"),"강원도","강원"),"특별자치",""),"전라남도","전남"),"전라북도","전북"),"아파트,","") -> 서울 강서구 양천로 177 (마곡동, 가양하수처리장직원아파트) 2동 206호 | C12: =경동전체1!E12 -> 0 | F12: =경동전체1!J12 -> 07520 | H12: =경동전체1!H12 -> 010-9524-9234 | I12: =경동전체1!I12&"" -> 010-9524-9234 | J12: 선불 | K12: =IF(LEFT(경동전체1!G12,1)="","따사룸",경동전체1!G12) -> 따사룸 | L12: ="1" -> 1 | M12: =IF(LEFT(경동전체1!D12,1)="2","비닐",IF(LEFT(경동전체1!O12,1)="박","박스","비닐")) -> 비닐 | N12: 1 | O12: 1 | P12: 1 | Q12: 1 | R12: ="50" -> 50 | S12: =경동전체1!B12 -> 6900 | T12: ="100" -> 100 | U12: ="0" -> 0 | V12: 0 | W12: 0 | X12: =SUBSTITUTE(SUBSTITUTE(SUBSTITUTE(SUBSTITUTE(SUBSTITUTE(SUBSTITUTE(SUBSTITUTE(SUBSTITUTE(SUBSTITUTE(SUBSTITUTE(SUBSTITUTE(SUBSTITUTE(SUBSTITUTE(경동전체1!D12,"마블아이보리","마블"),"100x100(1장)","(100)"),"50x50(4장)","(50)"),"실리콘테이프","테이프"),"★증정품★","★증★"),"(퍼즐)",""),"mm",""),"폭",""),"딜라이트우드","우드"),"그레캔버스","캔버스"),"소프트그레이","그레이"),"(퍼)",""),"아이보리","아이") -> 플러스♥25T아이(100)x1
A13: =경동전체1!A13 -> 2-1류춘렬 | B13: =SUBSTITUTE(SUBSTITUTE(SUBSTITUTE(SUBSTITUTE(SUBSTITUTE(SUBSTITUTE(SUBSTITUTE(SUBSTITUTE(SUBSTITUTE(SUBSTITUTE(SUBSTITUTE(SUBSTITUTE(SUBSTITUTE(경동전체1!K13,"특별시",""),"광역시",""),"직할시",""),"경기도",""),"충청북도","충북"),"충청남도","충남"),"경상북도","경북"),"경상남도","경남"),"강원도","강원"),"특별자치",""),"전라남도","전남"),"전라북도","전북"),"아파트,","") -> 대전 유성구 엑스포로 448 엑스포아파트 202동 1701호 | C13: =경동전체1!E13 -> 0 | F13: =경동전체1!J13 -> 34049 | H13: =경동전체1!H13 -> 010-8736-8737 | I13: =경동전체1!I13&"" -> 010-8736-8737 | J13: 선불 | K13: =IF(LEFT(경동전체1!G13,1)="","따사룸",경동전체1!G13) -> ★증정★테이프20mx1 | L13: ="1" -> 1 | M13: =IF(LEFT(경동전체1!D13,1)="2","비닐",IF(LEFT(경동전체1!O13,1)="박","박스","비닐")) -> 박스 | N13: 1 | O13: 1 | P13: 1 | Q13: 1 | R13: ="50" -> 50 | S13: =경동전체1!B13 -> 12100 | T13: ="100" -> 100 | U13: ="0" -> 0 | V13: 0 | W13: 0 | X13: =SUBSTITUTE(SUBSTITUTE(SUBSTITUTE(SUBSTITUTE(SUBSTITUTE(SUBSTITUTE(SUBSTITUTE(SUBSTITUTE(SUBSTITUTE(SUBSTITUTE(SUBSTITUTE(SUBSTITUTE(SUBSTITUTE(경동전체1!D13,"마블아이보리","마블"),"100x100(1장)","(100)"),"50x50(4장)","(50)"),"실리콘테이프","테이프"),"★증정품★","★증★"),"(퍼즐)",""),"mm",""),"폭",""),"딜라이트우드","우드"),"그레캔버스","캔버스"),"소프트그레이","그레이"),"(퍼)",""),"아이보리","아이") -> (110)17T퓨어아이5mx1
... A573: =경동전체1!A573 -> 0 | B573: =SUBSTITUTE(SUBSTITUTE(SUBSTITUTE(SUBSTITUTE(SUBSTITUTE(SUBSTITUTE(SUBSTITUTE(SUBSTITUTE(SUBSTITUTE(SUBSTITUTE(SUBSTITUTE(SUBSTITUTE(SUBSTITUTE(경동전체1!K573,"특별시",""),"광역시",""),"직할시",""),"경기도",""),"충청북도","충북"),"충청남도","충남"),"경상북도","경북"),"경상남도","경남"),"강원도","강원"),"특별자치",""),"전라남도","전남"),"전라북도","전북"),"아파트,","") | C573: =경동전체1!E573 -> 0 | F573: =경동전체1!J573 -> 0 | H573: =경동전체1!H573 -> 0 | I573: =경동전체1!I573&"" | J573: 선불 | K573: =IF(LEFT(경동전체1!G573,1)="","따사룸",경동전체1!G573) -> 따사룸 | L573: ="1" -> 1 | M573: =IF(LEFT(경동전체1!D573,1)="2","비닐",IF(LEFT(경동전체1!O573,1)="박","박스","비닐")) -> 비닐 | N573: 1 | O573: 1 | P573: 1 | Q573: 1 | R573: ="50" -> 50 | S573: =경동전체1!B573 -> 0 | T573: ="100" -> 100 | U573: ="0" -> 0 | V573: 0 | W573: 0 | X573: =SUBSTITUTE(SUBSTITUTE(SUBSTITUTE(SUBSTITUTE(SUBSTITUTE(SUBSTITUTE(SUBSTITUTE(SUBSTITUTE(SUBSTITUTE(SUBSTITUTE(SUBSTITUTE(SUBSTITUTE(SUBSTITUTE(경동전체1!D573,"마블아이보리","마블"),"100x100(1장)","(100)"),"50x50(4장)","(50)"),"실리콘테이프","테이프"),"★증정품★","★증★"),"(퍼즐)",""),"mm",""),"폭",""),"딜라이트우드","우드"),"그레캔버스","캔버스"),"소프트그레이","그레이"),"(퍼)",""),"아이보리","아이")
B574: =SUBSTITUTE(SUBSTITUTE(SUBSTITUTE(SUBSTITUTE(SUBSTITUTE(SUBSTITUTE(SUBSTITUTE(SUBSTITUTE(SUBSTITUTE(SUBSTITUTE(SUBSTITUTE(SUBSTITUTE(SUBSTITUTE(경동전체1!K574,"특별시",""),"광역시",""),"직할시",""),"경기도",""),"충청북도","충북"),"충청남도","충남"),"경상북도","경북"),"경상남도","경남"),"강원도","강원"),"특별자치",""),"전라남도","전남"),"전라북도","전북"),"아파트,","") | F574: =경동전체1!J574 -> 0 | J574: 선불 | K574: =IF(LEFT(경동전체1!G574,1)="","따사룸",경동전체1!G574) -> 따사룸 | N574: 1 | O574: 1 | P574: 1 | Q574: 1 | S574: =경동전체1!B574 -> 0 | V574: 0 | W574: 0 | X574: =SUBSTITUTE(SUBSTITUTE(SUBSTITUTE(SUBSTITUTE(SUBSTITUTE(SUBSTITUTE(SUBSTITUTE(SUBSTITUTE(SUBSTITUTE(SUBSTITUTE(SUBSTITUTE(SUBSTITUTE(SUBSTITUTE(경동전체1!D574,"마블아이보리","마블"),"100x100(1장)","(100)"),"50x50(4장)","(50)"),"실리콘테이프","테이프"),"★증정품★","★증★"),"(퍼즐)",""),"mm",""),"폭",""),"딜라이트우드","우드"),"그레캔버스","캔버스"),"소프트그레이","그레이"),"(퍼)",""),"아이보리","아이")
B575: =SUBSTITUTE(SUBSTITUTE(SUBSTITUTE(SUBSTITUTE(SUBSTITUTE(SUBSTITUTE(SUBSTITUTE(SUBSTITUTE(SUBSTITUTE(SUBSTITUTE(SUBSTITUTE(SUBSTITUTE(SUBSTITUTE(경동전체1!K575,"특별시",""),"광역시",""),"직할시",""),"경기도",""),"충청북도","충북"),"충청남도","충남"),"경상북도","경북"),"경상남도","경남"),"강원도","강원"),"특별자치",""),"전라남도","전남"),"전라북도","전북"),"아파트,","") | F575: =경동전체1!J575 -> 0 | J575: 선불 | K575: =IF(LEFT(경동전체1!G575,1)="","따사룸",경동전체1!G575) -> 따사룸 | N575: 1 | O575: 1 | P575: 1 | Q575: 1 | S575: =경동전체1!B575 -> 0 | V575: 0 | W575: 0 | X575: =SUBSTITUTE(SUBSTITUTE(SUBSTITUTE(SUBSTITUTE(SUBSTITUTE(SUBSTITUTE(SUBSTITUTE(SUBSTITUTE(SUBSTITUTE(SUBSTITUTE(SUBSTITUTE(SUBSTITUTE(SUBSTITUTE(경동전체1!D575,"마블아이보리","마블"),"100x100(1장)","(100)"),"50x50(4장)","(50)"),"실리콘테이프","테이프"),"★증정품★","★증★"),"(퍼즐)",""),"mm",""),"폭",""),"딜라이트우드","우드"),"그레캔버스","캔버스"),"소프트그레이","그레이"),"(퍼)",""),"아이보리","아이")
B576: =SUBSTITUTE(SUBSTITUTE(SUBSTITUTE(SUBSTITUTE(SUBSTITUTE(SUBSTITUTE(SUBSTITUTE(SUBSTITUTE(SUBSTITUTE(SUBSTITUTE(SUBSTITUTE(SUBSTITUTE(SUBSTITUTE(경동전체1!K576,"특별시",""),"광역시",""),"직할시",""),"경기도",""),"충청북도","충북"),"충청남도","충남"),"경상북도","경북"),"경상남도","경남"),"강원도","강원"),"특별자치",""),"전라남도","전남"),"전라북도","전북"),"아파트,","") | F576: =경동전체1!J576 -> 0 | J576: 선불 | K576: =IF(LEFT(경동전체1!G576,1)="","따사룸",경동전체1!G576) -> 따사룸 | N576: 1 | O576: 1 | P576: 1 | Q576: 1 | S576: =경동전체1!B576 -> 0 | V576: 0 | W576: 0 | X576: =SUBSTITUTE(SUBSTITUTE(SUBSTITUTE(SUBSTITUTE(SUBSTITUTE(SUBSTITUTE(SUBSTITUTE(SUBSTITUTE(SUBSTITUTE(SUBSTITUTE(SUBSTITUTE(SUBSTITUTE(SUBSTITUTE(경동전체1!D576,"마블아이보리","마블"),"100x100(1장)","(100)"),"50x50(4장)","(50)"),"실리콘테이프","테이프"),"★증정품★","★증★"),"(퍼즐)",""),"mm",""),"폭",""),"딜라이트우드","우드"),"그레캔버스","캔버스"),"소프트그레이","그레이"),"(퍼)",""),"아이보리","아이")
B577: =SUBSTITUTE(SUBSTITUTE(SUBSTITUTE(SUBSTITUTE(SUBSTITUTE(SUBSTITUTE(SUBSTITUTE(SUBSTITUTE(SUBSTITUTE(SUBSTITUTE(SUBSTITUTE(SUBSTITUTE(SUBSTITUTE(경동전체1!K577,"특별시",""),"광역시",""),"직할시",""),"경기도",""),"충청북도","충북"),"충청남도","충남"),"경상북도","경북"),"경상남도","경남"),"강원도","강원"),"특별자치",""),"전라남도","전남"),"전라북도","전북"),"아파트,","") | F577: =경동전체1!J577 -> 0 | J577: 선불 | K577: =IF(LEFT(경동전체1!G577,1)="","따사룸",경동전체1!G577) -> 따사룸 | N577: 1 | O577: 1 | P577: 1 | Q577: 1 | S577: =경동전체1!B577 -> 0 | V577: 0 | W577: 0 | X577: =SUBSTITUTE(SUBSTITUTE(SUBSTITUTE(SUBSTITUTE(SUBSTITUTE(SUBSTITUTE(SUBSTITUTE(SUBSTITUTE(SUBSTITUTE(SUBSTITUTE(SUBSTITUTE(SUBSTITUTE(SUBSTITUTE(경동전체1!D577,"마블아이보리","마블"),"100x100(1장)","(100)"),"50x50(4장)","(50)"),"실리콘테이프","테이프"),"★증정품★","★증★"),"(퍼즐)",""),"mm",""),"폭",""),"딜라이트우드","우드"),"그레캔버스","캔버스"),"소프트그레이","그레이"),"(퍼)",""),"아이보리","아이")

Sheet 경동전체1
A1: 받는분 | B1: 운임타입 | C1: 송장수량 | D1: 디자인 | E1: 배송메세지 | F1: 합포장 | G1: 비고 | H1: 받는분 전화번호 | I1: 받는분 전화번호 | J1: 우편번호 | K1: 받는분 주소 | O1: 포장상태
A2: 이주현★ | B2: 19400 | C2: 1 | D2: (140)17T퓨어아이보리8mx1 | E2: ★파손주의★문 앞에 놓아주세요 | G2: ★증정★테이프20mx1 | H2: 010-6412-7957 | I2: 010-6412-7957 | J2: 10562 | K2: 경기도 고양시 덕양구 원흥1로 31 (원흥동, 고양삼송엘에이치10단지아파트) 1004-502 | O2: =SUBSTITUTE(SUBSTITUTE(SUBSTITUTE(SUBSTITUTE(SUBSTITUTE(SUBSTITUTE(B2,"8100","박스"),"12100","박스"),"13800","박스"),"14700","박스"),"15400","박스"),"8600","박스") -> 19400
A3: 전준하★ | B3: 19400 | C3: 1 | D3: (140)17T퓨어아이보리8mx1 | E3: ★파손주의★물품 잘 확인해서 보내주세요. 배송시 문자주시고 문앞에 놓아주세요. 감사합니다. | G3: ★증정★테이프20mx1 | H3: 010-5153-1054 | I3: 010-5153-1054 | J3: 18405 | K3: 경기도 화성시 병점3로 117 (병점동, 안화동마을주공9단지) 901동 1605호 | O3: =SUBSTITUTE(SUBSTITUTE(SUBSTITUTE(SUBSTITUTE(SUBSTITUTE(SUBSTITUTE(B3,"8100","박스"),"12100","박스"),"13800","박스"),"14700","박스"),"15400","박스"),"8600","박스") -> 19400
A4: 나병준 | B4: 12700 | C4: 1 | D4: 25T(퍼즐)아이보리(50)x6 | H4: 010-9174-1121 | I4: 010-9174-1121 | J4: 16823 | K4: 경기도 용인시 수지구 손곡로 82 (동천동, 수진마을써니벨리아파트) 106동 506호 | O4: =SUBSTITUTE(SUBSTITUTE(SUBSTITUTE(SUBSTITUTE(SUBSTITUTE(SUBSTITUTE(B4,"8100","박스"),"12100","박스"),"13800","박스"),"14700","박스"),"15400","박스"),"8600","박스") -> 12700
A5: 4-3나대남 | D5: ★판매★테이프20mx1 | E5: 배송 전 미리 연락해 주세요 | F5: 합 | H5: 010-8965-2389 | I5: 0502-3214-2132 | J5: 01014 | K5: 서울특별시 강북구 4.19로13길 9 (수유동, 우이블루빌) 402호 | O5: =SUBSTITUTE(SUBSTITUTE(SUBSTITUTE(SUBSTITUTE(SUBSTITUTE(SUBSTITUTE(B5,"8100","박스"),"12100","박스"),"13800","박스"),"14700","박스"),"15400","박스"),"8600","박스")
A6: 4-1나대남★ | B6: 12700 | C6: 1 | D6: (110)17T마블아이보리5.5mx1 | E6: ★파손주의★ | H6: 010-8965-2389 | I6: 0502-3214-2132 | J6: 01014 | K6: 서울특별시 강북구 4.19로13길 9 (수유동, 우이블루빌) 402호 | O6: =SUBSTITUTE(SUBSTITUTE(SUBSTITUTE(SUBSTITUTE(SUBSTITUTE(SUBSTITUTE(B6,"8100","박스"),"12100","박스"),"13800","박스"),"14700","박스"),"15400","박스"),"8600","박스") -> 12700
A7: 4-2나대남 | B7: 12100 | C7: 1 | D7: (110)17T마블아이보리5mx1 | E7: 배송 전 미리 연락해 주세요 | G7: ★증정★테이프20mx3 | H7: 010-8965-2389 | I7: 0502-3214-2132 | J7: 01014 | K7: 서울특별시 강북구 4.19로13길 9 (수유동, 우이블루빌) 402호 | O7: =SUBSTITUTE(SUBSTITUTE(SUBSTITUTE(SUBSTITUTE(SUBSTITUTE(SUBSTITUTE(B7,"8100","박스"),"12100","박스"),"13800","박스"),"14700","박스"),"15400","박스"),"8600","박스") -> 박스
A8: 4-3나대남 | B8: 12100 | C8: 1 | D8: (110)17T마블아이보리5mx1 | E8: 배송 전 미리 연락해 주세요 | F8: 합 | H8: 010-8965-2389 | I8: 0502-3214-2132 | J8: 01014 | K8: 서울특별시 강북구 4.19로13길 9 (수유동, 우이블루빌) 402호 | O8: =SUBSTITUTE(SUBSTITUTE(SUBSTITUTE(SUBSTITUTE(SUBSTITUTE(SUBSTITUTE(B8,"8100","박스"),"12100","박스"),"13800","박스"),"14700","박스"),"15400","박스"),"8600","박스") -> 박스
A9: 4-4나대남 | B9: 13800 | C9: 1 | D9: (120)17T마블아이보리3mx1 | E9: 배송 전 미리 연락해 주세요 | F9: 합 | H9: 010-8965-2389 | I9: 0502-3214-2132 | J9: 01014 | K9: 서울특별시 강북구 4.19로13길 9 (수유동, 우이블루빌) 402호 | O9: =SUBSTITUTE(SUBSTITUTE(SUBSTITUTE(SUBSTITUTE(SUBSTITUTE(SUBSTITUTE(B9,"8100","박스"),"12100","박스"),"13800","박스"),"14700","박스"),"15400","박스"),"8600","박스") -> 박스
A10: 4-4나대남 | D10: (120)17T마블아이보리2mx1 | E10: 배송 전 미리 연락해 주세요 | F10: 합 | H10: 010-8965-2389 | I10: 0502-3214-2132 | J10: 01014 | K10: 서울특별시 강북구 4.19로13길 9 (수유동, 우이블루빌) 402호 | O10: =SUBSTITUTE(SUBSTITUTE(SUBSTITUTE(SUBSTITUTE(SUBSTITUTE(SUBSTITUTE(B10,"8100","박스"),"12100","박스"),"13800","박스"),"14700","박스"),"15400","박스"),"8600","박스")
A11: 최규철 | B11: 8600 | C11: 1 | D11: (140)6T소프트그레이2mx1 | H11: 010-8823-9437 | I11: 010-8823-9437 | J11: 37107 | K11: 경상북도 상주시 이안면 양범안룡길 80 (이안면) 양범교회 | O11: =SUBSTITUTE(SUBSTITUTE(SUBSTITUTE(SUBSTITUTE(SUBSTITUTE(SUBSTITUTE(B11,"8100","박스"),"12100","박스"),"13800","박스"),"14700","박스"),"15400","박스"),"8600","박스") -> 박스
A12: 한정우 | B12: 6900 | C12: 1 | D12: 플러스♥25T아이(100)x1 | H12: 010-9524-9234 | I12: 010-9524-9234 | J12: 07520 | K12: 서울특별시 강서구 양천로 177 (마곡동, 가양하수처리장직원아파트) 2동 206호 | O12: =SUBSTITUTE(SUBSTITUTE(SUBSTITUTE(SUBSTITUTE(SUBSTITUTE(SUBSTITUTE(B12,"8100","박스"),"12100","박스"),"13800","박스"),"14700","박스"),"15400","박스"),"8600","박스") -> 6900
A13: 2-1류춘렬 | B13: 12100 | C13: 1 | D13: (110)17T퓨어아이보리5mx1 | G13: ★증정★테이프20mx1 | H13: 010-8736-8737 | I13: 010-8736-8737 | J13: 34049 | K13: 대전광역시 유성구 엑스포로 448 엑스포아파트 202동 1701호 | O13: =SUBSTITUTE(SUBSTITUTE(SUBSTITUTE(SUBSTITUTE(SUBSTITUTE(SUBSTITUTE(B13,"8100","박스"),"12100","박스"),"13800","박스"),"14700","박스"),"15400","박스"),"8600","박스") -> 박스
A14: 2-2류춘렬 | B14: 12100 | C14: 1 | D14: (110)17T퓨어아이보리5mx1 | H14: 010-8736-8737 | I14: 010-8736-8737 | J14: 34049 | K14: 대전광역시 유성구 엑스포로 448 엑스포아파트 202동 1701호 | O14: =SUBSTITUTE(SUBSTITUTE(SUBSTITUTE(SUBSTITUTE(SUBSTITUTE(SUBSTITUTE(B14,"8100","박스"),"12100","박스"),"13800","박스"),"14700","박스"),"15400","박스"),"8600","박스") -> 박스
A15: 서혜린 | B15: 6900 | C15: 1 | D15: 25T(퍼즐)아이보리(50)x2 | H15: 010-3959-9166 | I15: 010-3959-9166 | J15: 17066 | K15: 경기도 용인시 기흥구 기흥역로58번길 56 (구갈동, 기흥역 파크 푸르지오) 301동3302호 | O15: =SUBSTITUTE(SUBSTITUTE(SUBSTITUTE(SUBSTITUTE(SUBSTITUTE(SUBSTITUTE(B15,"8100","박스"),"12100","박스"),"13800","박스"),"14700","박스"),"15400","박스"),"8600","박스") -> 6900
A16: 최향 | B16: 8600 | C16: 1 | D16: (120)17T소프트그레이2mx1 | H16: 010-5550-1258 | I16: 010-5550-1258 | J16: 11748 | K16: 경기도 의정부시 시민로 287 (신곡동) 이편한세상 신곡파크비스타 109동301호 | O16: =SUBSTITUTE(SUBSTITUTE(SUBSTITUTE(SUBSTITUTE(SUBSTITUTE(SUBSTITUTE(B16,"8100","박스"),"12100","박스"),"13800","박스"),"14700","박스"),"15400","박스"),"8600","박스") -> 박스
A17: 2-1이규원 | B17: 10700 | C17: 1 | D17: 25T(퍼즐)아이보리(100)x5 | E17: 부재시 문앞에 놔주세용 | H17: 010-8919-4157 | I17: 010-8919-4157 | J17: 11941 | K17: 경기도 구리시 원수택로32번길 60 (수택동, 성경아파트) 3동 402호 | O17: =SUBSTITUTE(SUBSTITUTE(SUBSTITUTE(SUBSTITUTE(SUBSTITUTE(SUBSTITUTE(B17,"8100","박스"),"12100","박스"),"13800","박스"),"14700","박스"),"15400","박스"),"8600","박스") -> 10700
A18: 2-2이규원 | B18: 10700 | C18: 1 | D18: 25T(퍼즐)아이보리(100)x3 | E18: 부재시 문앞에 놔주세용 | F18: 합 | H18: 010-8919-4157 | I18: 010-8919-4157 | J18: 11941 | K18: 경기도 구리시 원수택로32번길 60 (수택동, 성경아파트) 3동 402호 | O18: =SUBSTITUTE(SUBSTITUTE(SUBSTITUTE(SUBSTITUTE(SUBSTITUTE(SUBSTITUTE(B18,"8100","박스"),"12100","박스"),"13800","박스"),"14700","박스"),"15400","박스"),"8600","박스") -> 10700
A19: 2-2이규원 | D19: 25T(퍼즐)아이보리(50)x2 | E19: 부재시 문앞에 놔주세용 | F19: 합 | H19: 010-8919-4157 | I19: 010-8919-4157 | J19: 11941 | K19: 경기도 구리시 원수택로32번길 60 (수택동, 성경아파트) 3동 402호 | O19: =SUBSTITUTE(SUBSTITUTE(SUBSTITUTE(SUBSTITUTE(SUBSTITUTE(SUBSTITUTE(B19,"8100","박스"),"12100","박스"),"13800","박스"),"14700","박스"),"15400","박스"),"8600","박스")
A20: 2-1김예찬 | B20: 10700 | C20: 1 | D20: 25T(퍼즐)아이보리(100)x5 | H20: 010-6886-3860 | I20: 010-6886-3860 | J20: 34899 | K20: 대전광역시 중구 계백로1615번길 34 (유천동, 현대아파트) 113동 1407호 | O20: =SUBSTITUTE(SUBSTITUTE(SUBSTITUTE(SUBSTITUTE(SUBSTITUTE(SUBSTITUTE(B20,"8100","박스"),"12100","박스"),"13800","박스"),"14700","박스"),"15400","박스"),"8600","박스") -> 10700
A21: 2-2김예찬 | B21: 8600 | C21: 1 | D21: 25T(퍼즐)아이보리(100)x4 | H21: 010-6886-3860 | I21: 010-6886-3860 | J21: 34899 | K21: 대전광역시 중구 계백로1615번길 34 (유천동, 현대아파트) 113동 1407호 | O21: =SUBSTITUTE(SUBSTITUTE(SUBSTITUTE(SUBSTITUTE(SUBSTITUTE(SUBSTITUTE(B21,"8100","박스"),"12100","박스"),"13800","박스"),"14700","박스"),"15400","박스"),"8600","박스") -> 박스
A22: 2-1최영미 | B22: 8600 | C22: 1 | D22: 25T(퍼즐)아이보리(100)x4 | H22: 010-5574-4480 | I22: 010-5574-4480 | J22: 10931 | K22: 경기도 파주시 시청로 85 (아동동, 신안실크밸리2차 아파트) 206동303호 | O22: =SUBSTITUTE(SUBSTITUTE(SUBSTITUTE(SUBSTITUTE(SUBSTITUTE(SUBSTITUTE(B22,"8100","박스"),"12100","박스"),"13800","박스"),"14700","박스"),"15400","박스"),"8600","박스") -> 박스
A23: 2-2최영미 | B23: 8600 | C23: 1 | D23: 25T(퍼즐)아이보리(100)x4 | H23: 010-5574-4480 | I23: 010-5574-4480 | J23: 10931 | K23: 경기도 파주시 시청로 85 (아동동, 신안실크밸리2차 아파트) 206동303호 | O23: =SUBSTITUTE(SUBSTITUTE(SUBSTITUTE(SUBSTITUTE(SUBSTITUTE(SUBSTITUTE(B23,"8100","박스"),"12100","박스"),"13800","박스"),"14700","박스"),"15400","박스"),"8600","박스") -> 박스
A24: 문경은 | B24: 15400 | C24: 1 | D24: (140)12T퓨어아이보리5mx1 | G24: ★증정★테이프20mx1 | H24: 010-3537-9446 | I24: 010-3537-9446 | J24: 06920 | K24: 서울특별시 동작구 만양로 19 (노량진동, 상도신동아리버파크아파트) 707동 1405호 | O24: =SUBSTITUTE(SUBSTITUTE(SUBSTITUTE(SUBSTITUTE(SUBSTITUTE(SUBSTITUTE(B24,"8100","박스"),"12100","박스"),"13800","박스"),"14700","박스"),"15400","박스"),"8600","박스") -> 박스
A25: 이영진 | D25: (110)9T도그프린트7.5mx1 | E25: 현관문 앞에다가 나둬두세요~ | F25: 합 | H25: 010-3013-8148 | I25: 010-3013-8148 | J25: 11611 | K25: 경기도 의정부시 가금로34번길 23 (가능동, 힐스테이트 녹양역) 103동2302호 | O25: =SUBSTITUTE(SUBSTITUTE(SUBSTITUTE(SUBSTITUTE(SUBSTITUTE(SUBSTITUTE(B25,"8100","박스"),"12100","박스"),"13800","박스"),"14700","박스"),"15400","박스"),"8600","박스")
A26: 이영진 | B26: 15400 | C26: 1 | D26: (140)9T도그프린트2.5mx1 | E26: 현관문 앞에다가 나둬두세요~ | F26: 합 | G26: ★증정★테이프20mx1 | H26: 010-3013-8148 | I26: 010-3013-8148 | J26: 11611 | K26: 경기도 의정부시 가금로34번길 23 (가능동, 힐스테이트 녹양역) 103동2302호 | O26: =SUBSTITUTE(SUBSTITUTE(SUBSTITUTE(SUBSTITUTE(SUBSTITUTE(SUBSTITUTE(B26,"8100","박스"),"12100","박스"),"13800","박스"),"14700","박스"),"15400","박스"),"8600","박스") -> 박스
A27: 권석영 | B27: 6900 | C27: 1 | D27: 플러스♥25T아이(100)x1 | H27: 010-6208-9305 | I27: 010-6208-9305 | J27: 41408 | K27: 대구광역시 북구 구리로 183-28 (학정동, 두산아파트) 201동 204호 | O27: =SUBSTITUTE(SUBSTITUTE(SUBSTITUTE(SUBSTITUTE(SUBSTITUTE(SUBSTITUTE(B27,"8100","박스"),"12100","박스"),"13800","박스"),"14700","박스"),"15400","박스"),"8600","박스") -> 6900
A28: 3-1고정일 | B28: 12700 | C28: 1 | D28: 25T(퍼즐)아이보리(100)x6 | H28: 010-5436-3781 | I28: 010-5436-3781 | J28: 34368 | K28: 대전광역시 대덕구 대화로 160 (대화동, 산업용재유통상가) 1동 207호 | O28: =SUBSTITUTE(SUBSTITUTE(SUBSTITUTE(SUBSTITUTE(SUBSTITUTE(SUBSTITUTE(B28,"8100","박스"),"12100","박스"),"13800","박스"),"14700","박스"),"15400","박스"),"8600","박스") -> 12700
A29: 3-2고정일 | B29: 12700 | C29: 1 | D29: 25T(퍼즐)아이보리(100)x6 | H29: 010-5436-3781 | I29: 010-5436-3781 | J29: 34368 | K29: 대전광역시 대덕구 대화로 160 (대화동, 산업용재유통상가) 1동 207호 | O29: =SUBSTITUTE(SUBSTITUTE(SUBSTITUTE(SUBSTITUTE(SUBSTITUTE(SUBSTITUTE(B29,"8100","박스"),"12100","박스"),"13800","박스"),"14700","박스"),"15400","박스"),"8600","박스") -> 12700
A30: 3-3고정일 | B30: 8600 | C30: 1 | D30: 25T(퍼즐)블루(100)x2 | F30: 합 | H30: 010-5436-3781 | I30: 010-5436-3781 | J30: 34368 | K30: 대전광역시 대덕구 대화로 160 (대화동, 산업용재유통상가) 1동 207호 | O30: =SUBSTITUTE(SUBSTITUTE(SUBSTITUTE(SUBSTITUTE(SUBSTITUTE(SUBSTITUTE(B30,"8100","박스"),"12100","박스"),"13800","박스"),"14700","박스"),"15400","박스"),"8600","박스") -> 박스
A31: 3-3고정일 | D31: 25T(퍼즐)핑크(100)x2 | F31: 합 | H31: 010-5436-3781 | I31: 010-5436-3781 | J31: 34368 | K31: 대전광역시 대덕구 대화로 160 (대화동, 산업용재유통상가) 1동 207호 | O31: =SUBSTITUTE(SUBSTITUTE(SUBSTITUTE(SUBSTITUTE(SUBSTITUTE(SUBSTITUTE(B31,"8100","박스"),"12100","박스"),"13800","박스"),"14700","박스"),"15400","박스"),"8600","박스")
A32: 3-1지찬미 | B32: 10700 | C32: 1 | D32: 25T(퍼즐)아이보리(100)x5 | H32: 010-4856-8776 | I32: 0502-3513-7025 | J32: 24279 | K32: 강원도 춘천시 백령로 215 (후평동, 춘천일성트루엘더퍼스트아파트) 107-1304 | O32: =SUBSTITUTE(SUBSTITUTE(SUBSTITUTE(SUBSTITUTE(SUBSTITUTE(SUBSTITUTE(B32,"8100","박스"),"12100","박스"),"13800","박스"),"14700","박스"),"15400","박스"),"8600","박스") -> 10700
A33: 3-2지찬미 | B33: 10700 | C33: 1 | D33: 25T(퍼즐)아이보리(100)x5 | H33: 010-4856-8776 | I33: 0502-3513-7025 | J33: 24279 | K33: 강원도 춘천시 백령로 215 (후평동, 춘천일성트루엘더퍼스트아파트) 107-1304 | O33: =SUBSTITUTE(SUBSTITUTE(SUBSTITUTE(SUBSTITUTE(SUBSTITUTE(SUBSTITUTE(B33,"8100","박스"),"12100","박스"),"13800","박스"),"14700","박스"),"15400","박스"),"8600","박스") -> 10700
A34: 3-3지찬미 | B34: 10700 | C34: 1 | D34: 25T(퍼즐)아이보리(100)x5 | H34: 010-4856-8776 | I34: 0502-3513-7025 | J34: 24279 | K34: 강원도 춘천시 백령로 215 (후평동, 춘천일성트루엘더퍼스트아파트) 107-1304 | O34: =SUBSTITUTE(SUBSTITUTE(SUBSTITUTE(SUBSTITUTE(SUBSTITUTE(SUBSTITUTE(B34,"8100","박스"),"12100","박스"),"13800","박스"),"14700","박스"),"15400","박스"),"8600","박스") -> 10700
A35: 정다훈 | B35: 10700 | C35: 1 | D35: 40T(퍼즐)아이보리(100)x3 | E35: 배송 전 미리 연락해 주세요 | H35: 010-9490-8874 | I35: 010-9490-8874 | J35: 16868 | K35: 경기도 용인시 수지구 용구대로 2720 (죽전동, 현암마을동성2차아파트) 203동 1302호 | O35: =SUBSTITUTE(SUBSTITUTE(SUBSTITUTE(SUBSTITUTE(SUBSTITUTE(SUBSTITUTE(B35,"8100","박스"),"12100","박스"),"13800","박스"),"14700","박스"),"15400","박스"),"8600","박스") -> 10700
A36: 3-1이슬 | B36: 12700 | C36: 1 | D36: 25T(퍼즐)아이보리(100)x6 | H36: 010-5424-9068 | I36: 010-5424-9068 | J36: 12603 | K36: 경기도 여주시 산북면 상품로 72 (산북면) 1층 102호 | O36: =SUBSTITUTE(SUBSTITUTE(SUBSTITUTE(SUBSTITUTE(SUBSTITUTE(SUBSTITUTE(B36,"8100","박스"),"12100","박스"),"13800","박스"),"14700","박스"),"15400","박스"),"8600","박스") -> 12700
A37: 3-2이슬 | B37: 12700 | C37: 1 | D37: 25T(퍼즐)아이보리(100)x6 | H37: 010-5424-9068 | I37: 010-5424-9068 | J37: 12603 | K37: 경기도 여주시 산북면 상품로 72 (산북면) 1층 102호 | O37: =SUBSTITUTE(SUBSTITUTE(SUBSTITUTE(SUBSTITUTE(SUBSTITUTE(SUBSTITUTE(B37,"8100","박스"),"12100","박스"),"13800","박스"),"14700","박스"),"15400","박스"),"8600","박스") -> 12700
A38: 3-3이슬 | B38: 12700 | C38: 1 | D38: 25T(퍼즐)아이보리(100)x6 | H38: 010-5424-9068 | I38: 010-5424-9068 | J38: 12603 | K38: 경기도 여주시 산북면 상품로 72 (산북면) 1층 102호 | O38: =SUBSTITUTE(SUBSTITUTE(SUBSTITUTE(SUBSTITUTE(SUBSTITUTE(SUBSTITUTE(B38,"8100","박스"),"12100","박스"),"13800","박스"),"14700","박스"),"15400","박스"),"8600","박스") -> 12700
A39: 3-1김영국 | B39: 15400 | C39: 1 | D39: (140)17T퓨어아이보리4mx1 | G39: ★증정★테이프20mx3 | H39: 010-9080-1385 | I39: 010-9080-1385 | J39: 55150 | K39: 전북특별자치도 전주시 덕진구 세병로 130 (송천동2가, 에코시티 데시앙 네스트) 802동1403호 | O39: =SUBSTITUTE(SUBSTITUTE(SUBSTITUTE(SUBSTITUTE(SUBSTITUTE(SUBSTITUTE(B39,"8100","박스"),"12100","박스"),"13800","박스"),"14700","박스"),"15400","박스"),"8600","박스") -> 박스
A40: 3-2김영국 | B40: 15400 | C40: 1 | D40: (140)17T퓨어아이보리2.5mx1 | H40: 010-9080-1385 | I40: 010-9080-1385 | J40: 55150 | K40: 전북특별자치도 전주시 덕진구 세병로 130 (송천동2가, 에코시티 데시앙 네스트) 802동1403호 | O40: =SUBSTITUTE(SUBSTITUTE(SUBSTITUTE(SUBSTITUTE(SUBSTITUTE(SUBSTITUTE(B40,"8100","박스"),"12100","박스"),"13800","박스"),"14700","박스"),"15400","박스"),"8600","박스") -> 박스
...
