Workbook
Name 경동1: 송장화2!$B$2:$D$264,송장화2!$H$2:$O$264

Sheet 발송처리
A1: 상품주문번호 | B1: 주문번호 | C1: 배송속성 | D1: 풀필먼트사(주문 기준) | E1: 배송방법(구매자 요청) | F1: 배송방법 | G1: 택배사 | H1: 송장번호 | I1: 발송일 | J1: 판매채널 | K1: 구매자명 | L1: 구매자ID | M1: 수취인명 | N1: 주문상태 | O1: 주문세부상태 | P1: 결제위치 | Q1: 결제일 | R1: 상품번호 | S1: 상품명 | T1: 상품종류 | U1: 반품안심케어 | V1: 옵션정보 | W1: 옵션관리코드 | X1: 수량 | Y1: 옵션가격 | Z1: 상품가격 | AA1: 최종 상품별 할인액 | AB1: 판매자 부담 할인액 | AC1: 최종 상품별 총 주문금액 | AD1: 사은품 | AE1: 발주확인일 | AF1: 발송기한 | AG1: 발송처리일 | AH1: 송장출력일 | AI1: 배송비 형태 | AJ1: 배송비 묶음번호 | AK1: 배송비 유형 | AL1: 배송비 합계 | AM1: 제주/도서 추가배송비 | AN1: 배송비 할인액 | AO1: 판매자 상품코드 | AP1: 수취인연락처1 | AQ1: 수취인연락처2 | AR1: 통합배송지 | AS1: 기본배송지 | AT1: 상세배송지 | AU1: 구매자연락처 | AV1: 우편번호 | AW1: 배송메세지 | AX1: 결제수단 | AY1: 매출연동 수수료 | AZ1: 정산예정금액 | BA1: 개인통관고유부호 | BB1: 주문일시 | BC1: 네이버페이 주문관리 수수료 | BD1: 출고지 | BE1: 마지막 유입경로
A2: 2025121699647131 | B2: 2025121612584111 | C2: 당일발송 | E2: 택배,등기,소포 | F2: 택배,등기,소포 | G2: 로젠택배 | I2: 46007.334 | J2: 스마트스토어 | K2: 이주현 | L2: lejo**** | M2: 이주현 | N2: 발송대기 | O2: 신규주문 | P2: MOBILE | Q2: 46007.324 | R2: 6092903705 | S2: 따사룸 층간소음매트 아기 유아 거실 롤매트 놀이방 셀프시공 마블아이보리 70x50x1.7cm | T2: 조합형옵션상품 | U2: 비대상 | V2: ⛄홀리데이⛄디자인: 🔥HOT🔥퓨어아이보리 / 두께 / 폭: 1.7cm/140cm / 길이: 800cm | X2: 1 | Y2: 280500 | Z2: 19800 | AA2: 38220 | AB2: 38220 | AC2: 262080 | AD2: 10만원 이상 / 2롤 이상 구매 시 → 실리콘 테이프 20m 증정! | AF2: 46008 | AI2: 무료 | AJ2: 2025121628386394 | AK2: 무료 | AL2: 0 | AM2: 0 | AN2: 0 | AO2: A | AP2: 010-6412-7957 | AR2: 경기도 고양시 덕양구 원흥1로 31 (원흥동, 고양삼송엘에이치10단지아파트) 1004-502 | AS2: 경기도 고양시 덕양구 원흥1로 31 (원흥동, 고양삼송엘에이치10단지아파트) | AT2: 1004-502 | AU2: 010-6412-7957 | AV2: 10562 | AW2: 문 앞에 놓아주세요 | AX2: 신용카드 간편결제 | AY2: -10483 | AZ2: 242084 | BB2: 46007.317 | BC2: -9513 | BD2: (27642) 충청북도 음성군 금왕읍 금일로 259 (주)대승아이앤피 | BE2: 네이버쇼핑 외
A3: 2025121699509111 | B3: 2025121612487751 | C3: 일반배송 | E3: 택배,등기,소포 | F3: 택배,등기,소포 | G3: 로젠택배 | I3: 46007.334 | J3: 스마트스토어 | K3: 김기민 | L3: xoxo**** | M3: 김기민 | N3: 발송대기 | O3: 신규주문 | P3: MOBILE | Q3: 46007.311 | R3: 6710830644 | S3: 따사룸 층간소음 놀이방매트 유아 거실 PE 잘라쓰는 플레이 롤타입 발코니 매트 무직타이거 10T 110x50cm | T3: 조합형옵션상품 | U3: 비대상 | V3: 디자인선택: 딜라이트우드 / 두께선택: 15T / 길이선택: 110x200 | X3: 1 | Y3: 25520 | Z3: 500000 | AA3: 492960 | AB3: 492960 | AC3: 32560 | AF3: 46011 | AI3: 선결제 | AJ3: 2025121628368177 | AK3: 유료 | AL3: 5000 | AM3: 0 | AN3: 0 | AO3: B : 메인코드 / PE롤매트 / 일반관리 | AP3: 010-2914-9937 | AQ3: 010-2914-9937 | AR3: 경기도 파주시 문산읍 통일로 1750 (문산읍, 문산어울림) 문산어울림 105동 501호 | AS3: 경기도 파주시 문산읍 통일로 1750 (문산읍, 문산어울림) | AT3: 문산어울림 105동 501호 | AU3: 010-2914-9937 | AV3: 10811 | AX3: 신용카드 | AY3: -651 | AZ3: 30728 | BB3: 46007.311 | BC3: -1181 | BD3: (27642) 충청북도 음성군 금왕읍 금일로 259 (주)대승아이앤피 | BE3: 광고>쇼핑검색광고>쇼핑몰상품형
A4: 2025121698258721 | B4: 2025121611623791 | C4: 일반배송 | E4: 택배,등기,소포 | F4: 택배,등기,소포 | G4: 로젠택배 | I4: 46007.334 | J4: 스마트스토어 | K4: 김인혜 | L4: hi33**** | M4: 이미라 | N4: 발송대기 | O4: 신규주문 | P4: MOBILE | Q4: 46007.191 | R4: 2402587673 | S4: 따사룸 양면매트 PVC 일체형 층간소음 1800X700 | T4: 조합형옵션상품 | U4: 비대상 | V4: 디자인: 패브릭트윈 / 사이즈: XL [240x140 12T] | X4: 1 | Y4: 65600 | Z4: 238000 | AA4: 186430 | AB4: 186430 | AC4: 117170 | AF4: 46011 | AI4: 무료 | AJ4: 2025121628204362 | AK4: 무료 | AL4: 0 | AM4: 0 | AN4: 0 | AO4: B | AP4: 010-7184-2910 | AR4: 경기도 오산시 초평중앙로 10 (탑동, 오산세교 한신더휴) 2201동 903호 | AS4: 경기도 오산시 초평중앙로 10 (탑동, 오산세교 한신더휴) | AT4: 2201동 903호 | AU4: 010-7184-2910 | AV4: 18127 | AW4: 배송 전 미리 연락해 주세요 | AX4: 신용카드 간편결제 | AY4: -4686 | AZ4: 108231 | BB4: 46007.19 | BC4: -4253 | BD4: (27642) 충청북도 음성군 금왕읍 금일로 259 (주)대승아이앤피 | BE4: 네이버페이>홈(네이버쇼핑)
A5: 2025121696405561 | B5: 2025121610480061 | C5: 당일발송 | E5: 택배,등기,소포 | F5: 택배,등기,소포 | G5: 로젠택배 | I5: 46007.334 | J5: 스마트스토어 | K5: 전준하 | L5: ejzo**** | M5: 전준하 | N5: 발송대기 | O5: 신규주문 | P5: MOBILE | Q5: 46007.037 | R5: 6092903705 | S5: 따사룸 층간소음매트 아기 유아 거실 롤매트 놀이방 셀프시공 마블아이보리 70x50x1.7cm | T5: 조합형옵션상품 | U5: 비대상 | V5: ⛄홀리데이⛄디자인: 🔥HOT🔥퓨어아이보리 / 두께 / 폭: 1.7cm/140cm / 길이: 800cm | X5: 1 | Y5: 280500 | Z5: 19800 | AA5: 38220 | AB5: 38220 | AC5: 262080 | AD5: 10만원 이상 / 2롤 이상 구매 시 → 실리콘 테이프 20m 증정! | AF5: 46008 | AI5: 무료 | AJ5: 2025121627983379 | AK5: 무료 | AL5: 0 | AM5: 0 | AN5: 0 | AO5: A | AP5: 010-5153-1054 | AR5: 경기도 화성시 병점3로 117 (병점동, 안화동마을주공9단지) 901동 1605호 | AS5: 경기도 화성시 병점3로 117 (병점동, 안화동마을주공9단지) | AT5: 901동 1605호 | AU5: 010-5153-1054 | AV5: 18405 | AW5: 물품 잘 확인해서 보내주세요. 배송시 문자주시고 문앞에 놓아주세요. 감사합니다. | AX5: 신용카드 간편결제 | AY5: -10483 | AZ5: 242085 | BB5: 46007.037 | BC5: -9512 | BD5: (27642) 충청북도 음성군 금왕읍 금일로 259 (주)대승아이앤피 | BE5: 네이버페이>결제
A6: 2025121695559201 | B6: 2025121699939411 | C6: 당일발송 | E6: 택배,등기,소포 | F6: 택배,등기,소포 | G6: 로젠택배 | I6: 46007.334 | J6: 스마트스토어 | K6: 나병준 | L6: nb**** | M6: 나병준 | N6: 발송대기 | O6: 신규주문 | P6: MOBILE | Q6: 46007.012 | R6: 5994906898 | S6: 따사룸 층간소음 퍼즐매트 100x100x2.5 대형 바닐라아이보리 아기 유아 거실 놀이방 복도 | T6: 조합형옵션상품 | U6: 비대상 | V6: ⛄홀리데이⛄제품 타입: 퍼즐매트 / 색상: 바닐라아이보리 / (두께)사이즈: (25mm) 50x50 4장 | X6: 6 | Y6: 0 | Z6: 23000 | AA6: 31600 | AB6: 31600 | AC6: 106400 | AF6: 46008 | AI6: 무료 | AJ6: 2025121627879686 | AK6: 무료 | AL6: 0 | AM6: 0 | AN6: 0 | AO6: A | AP6: 010-9174-1121 | AR6: 경기도 용인시 수지구 손곡로 82 (동천동, 수진마을써니벨리아파트) 106동 506호 | AS6: 경기도 용인시 수지구 손곡로 82 (동천동, 수진마을써니벨리아파트) | AT6: 106동 506호 | AU6: 010-9174-1121 | AV6: 16823 | AX6: 신용카드 간편결제 | AY6: -2128 | AZ6: 100410 | BB6: 46007.012 | BC6: -3862 | BD6: (27642) 충청북도 음성군 금왕읍 금일로 259 (주)대승아이앤피 | BE6: 광고>브랜드검색상품(브랜드검색)
A7: 2025121594828291 | B7: 2025121599474451 | C7: 당일발송 | E7: 택배,등기,소포 | F7: 택배,등기,소포 | G7: 로젠택배 | I7: 46007.334 | J7: 스마트스토어 | K7: 나대남 | L7: bukh********** | M7: 나대남 | N7: 발송대기 | O7: 신규주문 | P7: MOBILE | Q7: 46006.995 | R7: 6092903705 | S7: [G001]20m | T7: 추가구성상품 | U7: 비대상 | V7: [G001]매트접합용 실리콘테이프: [G001]20m | W7: A | X7: 1 | Y7: 0 | Z7: 7900 | AA7: 0 | AB7: 0 | AC7: 7900 | AD7: 10만원 이상 / 2롤 이상 구매 시 → 실리콘 테이프 20m 증정! | AF7: 46008 | AI7: 무료 | AJ7: 2025121527792085 | AK7: 무료 | AL7: 0 | AM7: 0 | AN7: 0 | AO7: A | AP7: 0502-3214-2132 | AR7: 서울특별시 강북구 4.19로13길 9 (수유동, 우이블루빌) 402호 | AS7: 서울특별시 강북구 4.19로13길 9 (수유동, 우이블루빌) | AT7: 402호 | AU7: 010-8965-2389 | AV7: 01014 | AW7: 배송 전 미리 연락해 주세요 | AX7: 신용카드 간편결제 | AY7: -158 | AZ7: 7456 | BB7: 46006.995 | BC7: -286 | BD7: (27642) 충청북도 음성군 금왕읍 금일로 259 (주)대승아이앤피 | BE7: 광고>쇼핑검색광고>쇼핑몰상품형
A8: 2025121594828281 | B8: 2025121599474451 | C8: 당일발송 | E8: 택배,등기,소포 | F8: 택배,등기,소포 | G8: 로젠택배 | I8: 46007.334 | J8: 스마트스토어 | K8: 나대남 | L8: bukh********** | M8: 나대남 | N8: 발송대기 | O8: 신규주문 | P8: MOBILE | Q8: 46006.995 | R8: 6092903705 | S8: 따사룸 층간소음매트 아기 유아 거실 롤매트 놀이방 셀프시공 마블아이보리 70x50x1.7cm | T8: 조합형옵션상품 | U8: 비대상 | V8: ⛄홀리데이⛄디자인: 🏆BEST🏆마블아이보리 / 두께 / 폭: 1.7cm/110cm / 길이: 550cm | X8: 1 | Y8: 141100 | Z8: 19800 | AA8: 9100 | AB8: 9100 | AC8: 151800 | AD8: 10만원 이상 / 2롤 이상 구매 시 → 실리콘 테이프 20m 증정! | AF8: 46008 | AI8: 무료 | AJ8: 2025121527792085 | AK8: 무료 | AL8: 0 | AM8: 0 | AN8: 0 | AO8: A | AP8: 0502-3214-2132 | AR8: 서울특별시 강북구 4.19로13길 9 (수유동, 우이블루빌) 402호 | AS8: 서울특별시 강북구 4.19로13길 9 (수유동, 우이블루빌) | AT8: 402호 | AU8: 010-8965-2389 | AV8: 01014 | AW8: 배송 전 미리 연락해 주세요 | AX8: 신용카드 간편결제 | AY8: -3036 | AZ8: 143255 | BB8: 46006.995 | BC8: -5509 | BD8: (27642) 충청북도 음성군 금왕읍 금일로 259 (주)대승아이앤피 | BE8: 광고>쇼핑검색광고>쇼핑몰상품형
A9: 2025121594828271 | B9: 2025121599474451 | C9: 당일발송 | E9: 택배,등기,소포 | F9: 택배,등기,소포 | G9: 로젠택배 | I9: 46007.334 | J9: 스마트스토어 | K9: 나대남 | L9: bukh********** | M9: 나대남 | N9: 발송대기 | O9: 신규주문 | P9: MOBILE | Q9: 46006.995 | R9: 6092903705 | S9: 따사룸 층간소음매트 아기 유아 거실 롤매트 놀이방 셀프시공 마블아이보리 70x50x1.7cm | T9: 조합형옵션상품 | U9: 비대상 | V9: ⛄홀리데이⛄디자인: 🏆BEST🏆마블아이보리 / 두께 / 폭: 1.7cm/110cm / 길이: 500cm | X9: 2 | Y9: 127300 | Z9: 19800 | AA9: 45800 | AB9: 45800 | AC9: 248400 | AD9: 10만원 이상 / 2롤 이상 구매 시 → 실리콘 테이프 20m 증정! | AF9: 46008 | AI9: 무료 | AJ9: 2025121527792085 | AK9: 무료 | AL9: 0 | AM9: 0 | AN9: 0 | AO9: A | AP9: 0502-3214-2132 | AR9: 서울특별시 강북구 4.19로13길 9 (수유동, 우이블루빌) 402호 | AS9: 서울특별시 강북구 4.19로13길 9 (수유동, 우이블루빌) | AT9: 402호 | AU9: 010-8965-2389 | AV9: 01014 | AW9: 배송 전 미리 연락해 주세요 | AX9: 신용카드 간편결제 | AY9: -4968 | AZ9: 234416 | BB9: 46006.995 | BC9: -9016 | BD9: (27642) 충청북도 음성군 금왕읍 금일로 259 (주)대승아이앤피 | BE9: 광고>쇼핑검색광고>쇼핑몰상품형
A10: 2025121594828261 | B10: 2025121599474451 | C10: 당일발송 | E10: 택배,등기,소포 | F10: 택배,등기,소포 | G10: 로젠택배 | I10: 46007.334 | J10: 스마트스토어 | K10: 나대남 | L10: bukh********** | M10: 나대남 | N10: 발송대기 | O10: 신규주문 | P10: MOBILE | Q10: 46006.995 | R10: 6092903705 | S10: 따사룸 층간소음매트 아기 유아 거실 롤매트 놀이방 셀프시공 마블아이보리 70x50x1.7cm | T10: 조합형옵션상품 | U10: 비대상 | V10: ⛄홀리데이⛄디자인: 🏆BEST🏆마블아이보리 / 두께 / 폭: 1.7cm/120cm / 길이: 300cm | X10: 1 | Y10: 81100 | Z10: 19800 | AA10: 9100 | AB10: 9100 | AC10: 91800 | AD10: 10만원 이상 / 2롤 이상 구매 시 → 실리콘 테이프 20m 증정! | AF10: 46008 | AI10: 무료 | AJ10: 2025121527792085 | AK10: 무료 | AL10: 0 | AM10: 0 | AN10: 0 | AO10: A | AP10: 0502-3214-2132 | AR10: 서울특별시 강북구 4.19로13길 9 (수유동, 우이블루빌) 402호 | AS10: 서울특별시 강북구 4.19로13길 9 (수유동, 우이블루빌) | AT10: 402호 | AU10: 010-8965-2389 | AV10: 01014 | AW10: 배송 전 미리 연락해 주세요 | AX10: 신용카드 간편결제 | AY10: -1836 | AZ10: 86632 | BB10: 46006.995 | BC10: -3332 | BD10: (27642) 충청북도 음성군 금왕읍 금일로 259 (주)대승아이앤피 | BE10: 광고>쇼핑검색광고>쇼핑몰상품형
A11: 2025121594828251 | B11: 2025121599474451 | C11: 당일발송 | E11: 택배,등기,소포 | F11: 택배,등기,소포 | G11: 로젠택배 | I11: 46007.334 | J11: 스마트스토어 | K11: 나대남 | L11: bukh********** | M11: 나대남 | N11: 발송대기 | O11: 신규주문 | P11: MOBILE | Q11: 46006.995 | R11: 6092903705 | S11: 따사룸 층간소음매트 아기 유아 거실 롤매트 놀이방 셀프시공 마블아이보리 70x50x1.7cm | T11: 조합형옵션상품 | U11: 비대상 | V11: ⛄홀리데이⛄디자인: 🏆BEST🏆마블아이보리 / 두께 / 폭: 1.7cm/120cm / 길이: 200cm | X11: 1 | Y11: 50500 | Z11: 19800 | AA11: 11100 | AB11: 10100 | AC11: 59200 | AD11: 10만원 이상 / 2롤 이상 구매 시 → 실리콘 테이프 20m 증정! | AF11: 46008 | AI11: 무료 | AJ11: 2025121527792085 | AK11: 무료 | AL11: 0 | AM11: 0 | AN11: 0 | AO11: A | AP11: 0502-3214-2132 | AR11: 서울특별시 강북구 4.19로13길 9 (수유동, 우이블루빌) 402호 | AS11: 서울특별시 강북구 4.19로13길 9 (수유동, 우이블루빌) | AT11: 402호 | AU11: 010-8965-2389 | AV11: 01014 | AW11: 배송 전 미리 연락해 주세요 | AX11: 신용카드 간편결제 | AY11: -1204 | AZ11: 56812 | BB11: 46006.995 | BC11: -2184 | BD11: (27642) 충청북도 음성군 금왕읍 금일로 259 (주)대승아이앤피 | BE11: 광고>쇼핑검색광고>쇼핑몰상품형
A12: 2025121594230371 | B12: 2025121599095391 | C12: 당일발송 | E12: 택배,등기,소포 | F12: 택배,등기,소포 | G12: 로젠택배 | I12: 46007.334 | J12: 스마트스토어 | K12: 최규철 | L12: cg**** | M12: 최규철 | N12: 발송대기 | O12: 신규주문 | P12: PC | Q12: 46006.982 | R12: 4200445704 | S12: 따사룸 강아지매트 미끄럼방지 롤매트 애견 반려견 슬개골 방수 셀프시공 거실 복도 러그 마블아이보리 6T 110x50cm | T12: 조합형옵션상품 | U12: 비대상 | V12: ⛄홀리데이⛄디자인 선택: 소프트그레이 / 두께(폭): 6mm(폭140cm) / 길이(수량추가): 50cm | X12: 4 | Y12: 2800 | Z12: 15600 | AA12: 20800 | AB12: 20800 | AC12: 52800 | AD12: 10만원 이상 / 2롤 이상 구매 시 → 실리콘 테이프 20m 증정! | AF12: 46008 | AI12: 무료 | AJ12: 2025121527719676 | AK12: 무료 | AL12: 0 | AM12: 0 | AN12: 0 | AO12: A | AP12: 010-8823-9437 | AR12: 경상북도 상주시 이안면 양범안룡길 80 (이안면) 양범교회 | AS12: 경상북도 상주시 이안면 양범안룡길 80 (이안면) | AT12: 양범교회 | AU12: 010-8823-9437 | AV12: 37107 | AX12: 신용카드 간편결제 | AY12: -2112 | AZ12: 48773 | BB12: 46006.982 | BC12: -1915 | BD12: (27642) 충청북도 음성군 금왕읍 금일로 259 (주)대승아이앤피 | BE12: 네이버페이>홈(네이버쇼핑)
A13: 2025121594072441 | B13: 2025121598993781 | C13: 당일발송 | E13: 택배,등기,소포 | F13: 택배,등기,소포 | G13: 로젠택배 | I13: 46007.334 | J13: 스마트스토어 | K13: 한정우 | L13: hjwo*** | M13: 한정우 | N13: 발송대기 | O13: 신규주문 | P13: MOBILE | Q13: 46006.979 | R13: 5994906898 | S13: 따사룸 층간소음 퍼즐매트 100x100x2.5 대형 바닐라아이보리 아기 유아 거실 놀이방 복도 | T13: 조합형옵션상품 | U13: 비대상 | V13: ⛄홀리데이⛄제품 타입: ✨퍼즐매트 PLUS+✨ / 색상: 바닐라아이보리 / (두께)사이즈: (25mm) 100x100 1장 | X13: 1 | Y13: 4900 | Z13: 23000 | AA13: 5100 | AB13: 5100 | AC13: 22800 | AF13: 46008 | AI13: 무료 | AJ13: 2025121527700217 | AK13: 무료 | AL13: 0 | AM13: 0 | AN13: 0 | AO13: A | AP13: 010-9524-9234 | AR13: 서울특별시 강서구 양천로 177 (마곡동, 가양하수처리장직원아파트) 2동 206호 | AS13: 서울특별시 강서구 양천로 177 (마곡동, 가양하수처리장직원아파트) | AT13: 2동 206호 | AU13: 010-9524-9234 | AV13: 07520 | AX13: 신용카드 간편결제 | AY13: -456 | AZ13: 21517 | BB13: 46006.979 | BC13: -827 | BD13: (27642) 충청북도 음성군 금왕읍 금일로 259 (주)대승아이앤피 | BE13: 광고>쇼핑검색광고>쇼핑몰상품형
A14: 2025121593854551 | B14: 2025121598855331 | C14: 당일발송 | E14: 택배,등기,소포 | F14: 택배,등기,소포 | G14: 로젠택배 | I14: 46007.334 | J14: 스마트스토어 | K14: 류춘렬 | L14: pi**** | M14: 류춘렬 | N14: 발송대기 | O14: 신규주문 | P14: MOBILE | Q14: 46006.975 | R14: 6092903705 | S14: 따사룸 층간소음매트 아기 유아 거실 롤매트 놀이방 셀프시공 마블아이보리 70x50x1.7cm | T14: 조합형옵션상품 | U14: 비대상 | V14: ⛄홀리데이⛄디자인: 🔥HOT🔥퓨어아이보리 / 두께 / 폭: 1.7cm/110cm / 길이: 500cm | X14: 2 | Y14: 127300 | Z14: 19800 | AA14: 45800 | AB14: 45800 | AC14: 248400 | AD14: 10만원 이상 / 2롤 이상 구매 시 → 실리콘 테이프 20m 증정! | AF14: 46008 | AI14: 무료 | AJ14: 2025121527673529 | AK14: 무료 | AL14: 0 | AM14: 0 | AN14: 0 | AO14: A | AP14: 010-8736-8737 | AQ14: 010-8851-0917 | AR14: 대전광역시 유성구 엑스포로 448 엑스포아파트 202동 1701호 | AS14: 대전광역시 유성구 엑스포로 448 | AT14: 엑스포아파트 202동 1701호 | AU14: 010-8736-8737 | AV14: 34049 | AX14: 머니결제 | AY14: -4968 | AZ14: 234416 | BB14: 46006.975 | BC14: -9016 | BD14: (27642) 충청북도 음성군 금왕읍 금일로 259 (주)대승아이앤피 | BE14: 광고>쇼핑검색광고>쇼핑몰상품형
A15: 2025121591163141 | B15: 2025121597138861 | C15: 당일발송 | E15: 택배,등기,소포 | F15: 택배,등기,소포 | G15: 로젠택배 | I15: 46007.334 | J15: 스마트스토어 | K15: 서혜린 | L15: hael****** | M15: 서혜린 | N15: 발송대기 | O15: 신규주문 | P15: MOBILE | Q15: 46006.929 | R15: 5994906898 | S15: 따사룸 층간소음 퍼즐매트 100x100x2.5 대형 바닐라아이보리 아기 유아 거실 놀이방 복도 | T15: 조합형옵션상품 | U15: 비대상 | V15: ⛄홀리데이⛄제품 타입: 퍼즐매트 / 색상: 바닐라아이보리 / (두께)사이즈: (25mm) 50x50 4장 | X15: 2 | Y15: 0 | Z15: 23000 | AA15: 11280 | AB15: 11280 | AC15: 34720 | AF15: 46008 | AI15: 무료 | AJ15: 2025121527347328 | AK15: 무료 | AL15: 0 | AM15: 0 | AN15: 0 | AO15: A | AP15: 010-3959-9166 | AR15: 경기도 용인시 기흥구 기흥역로58번길 56 (구갈동, 기흥역 파크 푸르지오) 301동3302호 | AS15: 경기도 용인시 기흥구 기흥역로58번길 56 (구갈동, 기흥역 파크 푸르지오) | AT15: 301동3302호 | AU15: 010-3959-9166 | AV15: 17066 | AX15: 신용카드 간편결제 | AY15: -1388 | AZ15: 32072 | BB15: 46006.929 | BC15: -1260 | BD15: (27642) 충청북도 음성군 금왕읍 금일로 259 (주)대승아이앤피 | BE15: 네이버페이>홈(네이버쇼핑)
A16: 2025121590839141 | B16: 2025121596930501 | C16: 당일발송 | E16: 택배,등기,소포 | F16: 택배,등기,소포 | G16: 로젠택배 | I16: 46007.334 | J16: 스마트스토어 | K16: 최향 | L16: ehro****** | M16: 최향 | N16: 발송대기 | O16: 신규주문 | P16: MOBILE | Q16: 46006.924 | R16: 6092903705 | S16: 따사룸 층간소음매트 아기 유아 거실 롤매트 놀이방 셀프시공 마블아이보리 70x50x1.7cm | T16: 조합형옵션상품 | U16: 비대상 | V16: ⛄홀리데이⛄디자인: 소프트그레이 / 두께 / 폭: 1.7cm/120cm / 길이: 200cm | X16: 1 | Y16: 50500 | Z16: 19800 | AA16: 15220 | AB16: 15220 | AC16: 55080 | AD16: 10만원 이상 / 2롤 이상 구매 시 → 실리콘 테이프 20m 증정! | AF16: 46008 | AI16: 무료 | AJ16: 2025121527308404 | AK16: 무료 | AL16: 0 | AM16: 0 | AN16: 0 | AO16: A | AP16: 010-5550-1258 | AQ16: 010-5271-8385 | AR16: 경기도 의정부시 시민로 287 (신곡동) 이편한세상 신곡파크비스타 109동301호 | AS16: 경기도 의정부시 시민로 287 (신곡동) | AT16: 이편한세상 신곡파크비스타 109동301호 | AU16: 010-5550-1258 | AV16: 11748 | AX16: 신용카드 | AY16: -2203 | AZ16: 50878 | BB16: 46006.924 | BC16: -1999 | BD16: (27642) 충청북도 음성군 금왕읍 금일로 259 (주)대승아이앤피 | BE16: 쇼핑웹>구매내역>상품이미지
A17: 2025121590742721 | B17: 2025121596868131 | C17: 당일발송 | E17: 택배,등기,소포 | F17: 택배,등기,소포 | G17: 로젠택배 | I17: 46007.334 | J17: 스마트스토어 | K17: 이규원 | L17: dlrb****** | M17: 이규원 | N17: 발송대기 | O17: 신규주문 | P17: MOBILE | Q17: 46006.923 | R17: 5994906898 | S17: 따사룸 층간소음 퍼즐매트 100x100x2.5 대형 바닐라아이보리 아기 유아 거실 놀이방 복도 | T17: 조합형옵션상품 | U17: 비대상 | V17: ⛄홀리데이⛄제품 타입: 퍼즐매트 / 색상: 바닐라아이보리 / (두께)사이즈: (25mm) 100x100 1장 | X17: 8 | Y17: 0 | Z17: 23000 | AA17: 40800 | AB17: 40800 | AC17: 143200 | AF17: 46008 | AI17: 무료 | AJ17: 2025121527295400 | AK17: 무료 | AL17: 0 | AM17: 0 | AN17: 0 | AO17: A | AP17: 010-8919-4157 | AR17: 경기도 구리시 원수택로32번길 60 (수택동, 성경아파트) 3동 402호 | AS17: 경기도 구리시 원수택로32번길 60 (수택동, 성경아파트) | AT17: 3동 402호 | AU17: 010-8919-4157 | AV17: 11941 | AW17: 부재시 문앞에 놔주세용 | AX17: 신용카드 간편결제 | AY17: -5728 | AZ17: 132274 | BB17: 46006.923 | BC17: -5198 | BD17: (27642) 충청북도 음성군 금왕읍 금일로 259 (주)대승아이앤피 | BE17: 네이버쇼핑 외
A18: 2025121590742711 | B18: 2025121596868131 | C18: 당일발송 | E18: 택배,등기,소포 | F18: 택배,등기,소포 | G18: 로젠택배 | I18: 46007.334 | J18: 스마트스토어 | K18: 이규원 | L18: dlrb****** | M18: 이규원 | N18: 발송대기 | O18: 신규주문 | P18: MOBILE | Q18: 46006.923 | R18: 5994906898 | S18: 따사룸 층간소음 퍼즐매트 100x100x2.5 대형 바닐라아이보리 아기 유아 거실 놀이방 복도 | T18: 조합형옵션상품 | U18: 비대상 | V18: ⛄홀리데이⛄제품 타입: 퍼즐매트 / 색상: 바닐라아이보리 / (두께)사이즈: (25mm) 50x50 4장 | X18: 2 | Y18: 0 | Z18: 23000 | AA18: 11200 | AB18: 11200 | AC18: 34800 | AF18: 46008 | AI18: 무료 | AJ18: 2025121527295400 | AK18: 무료 | AL18: 0 | AM18: 0 | AN18: 0 | AO18: A | AP18: 010-8919-4157 | AR18: 경기도 구리시 원수택로32번길 60 (수택동, 성경아파트) 3동 402호 | AS18: 경기도 구리시 원수택로32번길 60 (수택동, 성경아파트) | AT18: 3동 402호 | AU18: 010-8919-4157 | AV18: 11941 | AW18: 부재시 문앞에 놔주세용 | AX18: 신용카드 간편결제 | AY18: -1392 | AZ18: 32145 | BB18: 46006.923 | BC18: -1263 | BD18: (27642) 충청북도 음성군 금왕읍 금일로 259 (주)대승아이앤피 | BE18: 네이버쇼핑 외
A19: 2025121590061171 | B19: 2025121596413351 | C19: 당일발송 | E19: 택배,등기,소포 | F19: 택배,등기,소포 | G19: 로젠택배 | I19: 46007.334 | J19: 스마트스토어 | K19: 김예찬 | L19: fl**** | M19: 김예찬 | N19: 발송대기 | O19: 신규주문 | P19: PC | Q19: 46006.912 | R19: 5994906898 | S19: 따사룸 층간소음 퍼즐매트 100x100x2.5 대형 바닐라아이보리 아기 유아 거실 놀이방 복도 | T19: 조합형옵션상품 | U19: 비대상 | V19: ⛄홀리데이⛄제품 타입: 퍼즐매트 / 색상: 바닐라아이보리 / (두께)사이즈: (25mm) 100x100 1장 | X19: 9 | Y19: 0 | Z19: 23000 | AA19: 45900 | AB19: 45900 | AC19: 161100 | AF19: 46008 | AI19: 무료 | AJ19: 2025121527209261 | AK19: 무료 | AL19: 0 | AM19: 0 | AN19: 0 | AO19: A | AP19: 010-6886-3860 | AR19: 대전광역시 중구 계백로1615번길 34 (유천동, 현대아파트) 113동 1407호 | AS19: 대전광역시 중구 계백로1615번길 34 (유천동, 현대아파트) | AT19: 113동 1407호 | AU19: 010-6886-3860 | AV19: 34899 | AX19: 신용카드 간편결제 | AY19: -6444 | AZ19: 148809 | BB19: 46006.912 | BC19: -5847 | BD19: (27642) 충청북도 음성군 금왕읍 금일로 259 (주)대승아이앤피 | BE19: 네이버플러스스토어검색>상품카드
A20: 2025121588680721 | B20: 2025121595501311 | C20: 당일발송 | E20: 택배,등기,소포 | F20: 택배,등기,소포 | G20: 로젠택배 | I20: 46007.334 | J20: 스마트스토어 | K20: 최영미 | L20: chl8*** | M20: 최영미 | N20: 발송대기 | O20: 신규주문 | P20: MOBILE | Q20: 46006.89 | R20: 5994906898 | S20: 따사룸 층간소음 퍼즐매트 100x100x2.5 대형 바닐라아이보리 아기 유아 거실 놀이방 복도 | T20: 조합형옵션상품 | U20: 비대상 | V20: ⛄홀리데이⛄제품 타입: 퍼즐매트 / 색상: 바닐라아이보리 / (두께)사이즈: (25mm) 100x100 1장 | X20: 8 | Y20: 0 | Z20: 23000 | AA20: 42800 | AB20: 41800 | AC20: 141200 | AF20: 46008 | AI20: 무료 | AJ20: 2025121527036557 | AK20: 무료 | AL20: 0 | AM20: 0 | AN20: 0 | AO20: A | AP20: 010-5574-4480 | AR20: 경기도 파주시 시청로 85 (아동동, 신안실크밸리2차 아파트) 206동303호 | AS20: 경기도 파주시 시청로 85 (아동동, 신안실크밸리2차 아파트) | AT20: 206동303호 | AU20: 010-5574-4480 | AV20: 10931 | AX20: 신용카드 간편결제 | AY20: -5688 | AZ20: 131351 | BB20: 46006.89 | BC20: -5161 | BD20: (27642) 충청북도 음성군 금왕읍 금일로 259 (주)대승아이앤피 | BE20: 네이버페이>홈(네이버쇼핑)
A21: 2025121587720071 | B21: 2025121594859701 | C21: 당일발송 | E21: 택배,등기,소포 | F21: 택배,등기,소포 | G21: 로젠택배 | I21: 46007.334 | J21: 스마트스토어 | K21: 문경은 | L21: dmjs**** | M21: 문경은 | N21: 발송대기 | O21: 신규주문 | P21: MOBILE | Q21: 46006.874 | R21: 6092903705 | S21: 따사룸 층간소음매트 아기 유아 거실 롤매트 놀이방 셀프시공 마블아이보리 70x50x1.7cm | T21: 조합형옵션상품 | U21: 비대상 | V21: ⛄홀리데이⛄디자인: 🔥HOT🔥퓨어아이보리 / 두께 / 폭: 1.2cm/140cm / 길이: 500cm | X21: 1 | Y21: 157300 | Z21: 19800 | AA21: 25900 | AB21: 25900 | AC21: 151200 | AD21: 10만원 이상 / 2롤 이상 구매 시 → 실리콘 테이프 20m 증정! | AF21: 46008 | AI21: 무료 | AJ21: 2025121526915878 | AK21: 무료 | AL21: 0 | AM21: 0 | AN21: 0 | AO21: A | AP21: 010-3537-9446 | AR21: 서울특별시 동작구 만양로 19 (노량진동, 상도신동아리버파크아파트) 707동 1405호 | AS21: 서울특별시 동작구 만양로 19 (노량진동, 상도신동아리버파크아파트) | AT21: 707동 1405호 | AU21: 010-3537-9446 | AV21: 06920 | AX21: 신용카드 간편결제 | AY21: -6048 | AZ21: 139664 | BB21: 46006.874 | BC21: -5488 | BD21: (27642) 충청북도 음성군 금왕읍 금일로 259 (주)대승아이앤피 | BE21: 마이쇼핑>장바구니(네이버쇼핑)
A22: 2025121584846521 | B22: 2025121592887421 | C22: 당일발송 | E22: 택배,등기,소포 | F22: 택배,등기,소포 | G22: 로젠택배 | I22: 46007.334 | J22: 스마트스토어 | K22: 이영진 | L22: jins******** | M22: 이영진 | N22: 발송대기 | O22: 신규주문 | P22: MOBILE | Q22: 46006.826 | R22: 4200445704 | S22: 따사룸 강아지매트 미끄럼방지 롤매트 애견 반려견 슬개골 방수 셀프시공 거실 복도 러그 마블아이보리 6T 110x50cm | T22: 조합형옵션상품 | U22: 비대상 | V22: ⛄홀리데이⛄디자인 선택: 도그프린트 / 두께(폭): 9mm(폭110cm) / 길이(수량추가): 50cm | X22: 15 | Y22: 500 | Z22: 15600 | AA22: 94350 | AB22: 94350 | AC22: 147150 | AD22: 10만원 이상 / 2롤 이상 구매 시 → 실리콘 테이프 20m 증정! | AF22: 46008 | AI22: 무료 | AJ22: 2025121526544856 | AK22: 무료 | AL22: 0 | AM22: 0 | AN22: 0 | AO22: A | AP22: 010-3013-8148 | AR22: 경기도 의정부시 가금로34번길 23 (가능동, 힐스테이트 녹양역) 103동2302호 | AS22: 경기도 의정부시 가금로34번길 23 (가능동, 힐스테이트 녹양역) | AT22: 103동2302호 | AU22: 010-3013-8148 | AV22: 11611 | AW22: 현관문 앞에다가 나둬두세요~ | AX22: 신용카드 간편결제 | AY22: -5886 | AZ22: 135923 | BB22: 46006.826 | BC22: -5341 | BD22: (27642) 충청북도 음성군 금왕읍 금일로 259 (주)대승아이앤피 | BE22: 네이버페이>홈(네이버쇼핑)
A23: 2025121584846511 | B23: 2025121592887421 | C23: 당일발송 | E23: 택배,등기,소포 | F23: 택배,등기,소포 | G23: 로젠택배 | I23: 46007.334 | J23: 스마트스토어 | K23: 이영진 | L23: jins******** | M23: 이영진 | N23: 발송대기 | O23: 신규주문 | P23: MOBILE | Q23: 46006.826 | R23: 4200445704 | S23: 따사룸 강아지매트 미끄럼방지 롤매트 애견 반려견 슬개골 방수 셀프시공 거실 복도 러그 마블아이보리 6T 110x50cm | T23: 조합형옵션상품 | U23: 비대상 | V23: ⛄홀리데이⛄디자인 선택: 도그프린트 / 두께(폭): 9mm(폭140cm) / 길이(수량추가): 50cm | X23: 5 | Y23: 3100 | Z23: 15600 | AA23: 26000 | AB23: 26000 | AC23: 67500 | AD23: 10만원 이상 / 2롤 이상 구매 시 → 실리콘 테이프 20m 증정! | AF23: 46008 | AI23: 무료 | AJ23: 2025121526544856 | AK23: 무료 | AL23: 0 | AM23: 0 | AN23: 0 | AO23: A | AP23: 010-3013-8148 | AR23: 경기도 의정부시 가금로34번길 23 (가능동, 힐스테이트 녹양역) 103동2302호 | AS23: 경기도 의정부시 가금로34번길 23 (가능동, 힐스테이트 녹양역) | AT23: 103동2302호 | AU23: 010-3013-8148 | AV23: 11611 | AW23: 현관문 앞에다가 나둬두세요~ | AX23: 신용카드 간편결제 | AY23: -2700 | AZ23: 62350 | BB23: 46006.826 | BC23: -2450 | BD23: (27642) 충청북도 음성군 금왕읍 금일로 259 (주)대승아이앤피 | BE23: 네이버페이>홈(네이버쇼핑)
A24: 2025121581144071 | B24: 2025121590296951 | C24: 당일발송 | E24: 택배,등기,소포 | F24: 택배,등기,소포 | G24: 로젠택배 | I24: 46007.334 | J24: 스마트스토어 | K24: 권석영 | L24: ks**** | M24: 권석영 | N24: 발송대기 | O24: 신규주문 | P24: MOBILE | Q24: 46006.753 | R24: 5994906898 | S24: 따사룸 층간소음 퍼즐매트 100x100x2.5 대형 바닐라아이보리 아기 유아 거실 놀이방 복도 | T24: 조합형옵션상품 | U24: 비대상 | V24: ⛄홀리데이⛄제품 타입: ✨퍼즐매트 PLUS+✨ / 색상: 바닐라아이보리 / (두께)사이즈: (25mm) 100x100 1장 | X24: 1 | Y24: 4900 | Z24: 23000 | AA24: 7100 | AB24: 6100 | AC24: 20800 | AF24: 46008 | AI24: 무료 | AJ24: 2025121526057035 | AK24: 무료 | AL24: 0 | AM24: 0 | AN24: 0 | AO24: A | AP24: 010-6208-9305 | AR24: 대구광역시 북구 구리로 183-28 (학정동, 두산아파트) 201동 204호 | AS24: 대구광역시 북구 구리로 183-28 (학정동, 두산아파트) | AT24: 201동 204호 | AU24: 010-6208-9305 | AV24: 41408 | AX24: 머니결제 | AY24: -872 | AZ24: 20137 | BB24: 46006.753 | BC24: -791 | BD24: (27642) 충청북도 음성군 금왕읍 금일로 259 (주)대승아이앤피 | BE24: 네이버페이>홈(네이버쇼핑)
A25: 2025121577697531 | B25: 2025121587969781 | C25: 당일발송 | E25: 택배,등기,소포 | F25: 택배,등기,소포 | G25: 로젠택배 | I25: 46007.334 | J25: 스마트스토어 | K25: 고정일 | L25: esde****** | M25: 고정일 | N25: 발송대기 | O25: 신규주문 | P25: PC | Q25: 46006.693 | R25: 5994906898 | S25: 따사룸 층간소음 퍼즐매트 100x100x2.5 대형 바닐라아이보리 아기 유아 거실 놀이방 복도 | T25: 조합형옵션상품 | U25: 비대상 | V25: ⛄홀리데이⛄제품 타입: 퍼즐매트 / 색상: 바닐라아이보리 / (두께)사이즈: (25mm) 100x100 1장 | X25: 12 | Y25: 0 | Z25: 23000 | AA25: 61200 | AB25: 61200 | AC25: 214800 | AF25: 46008 | AI25: 무료 | AJ25: 2025121525622634 | AK25: 무료 | AL25: 0 | AM25: 0 | AN25: 0 | AO25: A | AP25: 010-5436-3781 | AR25: 대전광역시 대덕구 대화로 160 (대화동, 산업용재유통상가) 1동 207호 | AS25: 대전광역시 대덕구 대화로 160 (대화동, 산업용재유통상가) | AT25: 1동 207호 | AU25: 010-5436-3781 | AV25: 34368 | AX25: 신용카드 간편결제 | AY25: -8592 | AZ25: 198411 | BB25: 46006.693 | BC25: -7797 | BD25: (27642) 충청북도 음성군 금왕읍 금일로 259 (주)대승아이앤피 | BE25: 검색>쇼핑검색(네이버쇼핑)
A26: 2025121577697521 | B26: 2025121587969781 | C26: 당일발송 | E26: 택배,등기,소포 | F26: 택배,등기,소포 | G26: 로젠택배 | I26: 46007.334 | J26: 스마트스토어 | K26: 고정일 | L26: esde****** | M26: 고정일 | N26: 발송대기 | O26: 신규주문 | P26: PC | Q26: 46006.693 | R26: 5994906898 | S26: 따사룸 층간소음 퍼즐매트 100x100x2.5 대형 바닐라아이보리 아기 유아 거실 놀이방 복도 | T26: 조합형옵션상품 | U26: 비대상 | V26: ⛄홀리데이⛄제품 타입: 퍼즐매트 / 색상: 스카이블루 / (두께)사이즈: (25mm) 100x100 1장 | X26: 2 | Y26: 0 | Z26: 23000 | AA26: 12200 | AB26: 11200 | AC26: 33800 | AF26: 46008 | AI26: 무료 | AJ26: 2025121525622634 | AK26: 무료 | AL26: 0 | AM26: 0 | AN26: 0 | AO26: A | AP26: 010-5436-3781 | AR26: 대전광역시 대덕구 대화로 160 (대화동, 산업용재유통상가) 1동 207호 | AS26: 대전광역시 대덕구 대화로 160 (대화동, 산업용재유통상가) | AT26: 1동 207호 | AU26: 010-5436-3781 | AV26: 34368 | AX26: 신용카드 간편결제 | AY26: -1392 | AZ26: 32146 | BB26: 46006.693 | BC26: -1262 | BD26: (27642) 충청북도 음성군 금왕읍 금일로 259 (주)대승아이앤피 | BE26: 검색>쇼핑검색(네이버쇼핑)
A27: 2025121577697511 | B27: 2025121587969781 | C27: 당일발송 | E27: 택배,등기,소포 | F27: 택배,등기,소포 | G27: 로젠택배 | I27: 46007.334 | J27: 스마트스토어 | K27: 고정일 | L27: esde****** | M27: 고정일 | N27: 발송대기 | O27: 신규주문 | P27: PC | Q27: 46006.693 | R27: 5994906898 | S27: 따사룸 층간소음 퍼즐매트 100x100x2.5 대형 바닐라아이보리 아기 유아 거실 놀이방 복도 | T27: 조합형옵션상품 | U27: 비대상 | V27: ⛄홀리데이⛄제품 타입: 퍼즐매트 / 색상: 파스텔핑크 / (두께)사이즈: (25mm) 100x100 1장 | X27: 2 | Y27: 0 | Z27: 23000 | AA27: 10200 | AB27: 10200 | AC27: 35800 | AF27: 46008 | AI27: 무료 | AJ27: 2025121525622634 | AK27: 무료 | AL27: 0 | AM27: 0 | AN27: 0 | AO27: A | AP27: 010-5436-3781 | AR27: 대전광역시 대덕구 대화로 160 (대화동, 산업용재유통상가) 1동 207호 | AS27: 대전광역시 대덕구 대화로 160 (대화동, 산업용재유통상가) | AT27: 1동 207호 | AU27: 010-5436-3781 | AV27: 34368 | AX27: 신용카드 간편결제 | AY27: -1432 | AZ27: 33069 | BB27: 46006.693 | BC27: -1299 | BD27: (27642) 충청북도 음성군 금왕읍 금일로 259 (주)대승아이앤피 | BE27: 검색>쇼핑검색(네이버쇼핑)
A28: 2025121576260771 | B28: 2025121587002511 | C28: 당일발송 | E28: 택배,등기,소포 | F28: 택배,등기,소포 | G28: 로젠택배 | I28: 46007.334 | J28: 스마트스토어 | K28: 지찬미 | L28: heeh****** | M28: 지찬미 | N28: 발송대기 | O28: 신규주문 | P28: MOBILE | Q28: 46006.672 | R28: 5994906898 | S28: 따사룸 층간소음 퍼즐매트 100x100x2.5 대형 바닐라아이보리 아기 유아 거실 놀이방 복도 | T28: 조합형옵션상품 | U28: 비대상 | V28: ⛄홀리데이⛄제품 타입: 퍼즐매트 / 색상: 바닐라아이보리 / (두께)사이즈: (25mm) 100x100 1장 | X28: 15 | Y28: 0 | Z28: 23000 | AA28: 78500 | AB28: 77500 | AC28: 266500 | AF28: 46008 | AI28: 무료 | AJ28: 2025121525440538 | AK28: 무료 | AL28: 0 | AM28: 0 | AN28: 0 | AO28: A | AP28: 0502-3513-7025 | AR28: 강원도 춘천시 백령로 215 (후평동, 춘천일성트루엘더퍼스트아파트) 107-1304 | AS28: 강원도 춘천시 백령로 215 (후평동, 춘천일성트루엘더퍼스트아파트) | AT28: 107-1304 | AU28: 010-4856-8776 | AV28: 24279 | AX28: 무통장입금 | AY28: -10700 | AZ28: 247091 | BB28: 46006.671 | BC28: -9709 | BD28: (27642) 충청북도 음성군 금왕읍 금일로 259 (주)대승아이앤피 | BE28: 검색>쇼핑검색(네이버쇼핑)
A29: 2025121574508471 | B29: 2025121585858441 | C29: 당일발송 | E29: 택배,등기,소포 | F29: 택배,등기,소포 | G29: 로젠택배 | I29: 46007.334 | J29: 스마트스토어 | K29: 정다훈 | L29: wjde****** | M29: 정다훈 | N29: 발송대기 | O29: 신규주문 | P29: MOBILE | Q29: 46006.644 | R29: 5994906898 | S29: 따사룸 층간소음 퍼즐매트 100x100x2.5 대형 바닐라아이보리 아기 유아 거실 놀이방 복도 | T29: 조합형옵션상품 | U29: 비대상 | V29: ⛄홀리데이⛄제품 타입: 퍼즐매트 / 색상: 바닐라아이보리 / (두께)사이즈: (40mm) 100x100 1장 | X29: 3 | Y29: 8400 | Z29: 23000 | AA29: 16300 | AB29: 16300 | AC29: 77900 | AF29: 46008 | AI29: 무료 | AJ29: 2025121525226011 | AK29: 무료 | AL29: 0 | AM29: 0 | AN29: 0 | AO29: A | AP29: 010-9490-8874 | AR29: 경기도 용인시 수지구 용구대로 2720 (죽전동, 현암마을동성2차아파트) 203동 1302호 | AS29: 경기도 용인시 수지구 용구대로 2720 (죽전동, 현암마을동성2차아파트) | AT29: 203동 1302호 | AU29: 010-9490-8874 | AV29: 16868 | AW29: 배송 전 미리 연락해 주세요 | AX29: 머니결제 | AY29: -1558 | AZ29: 73515 | BB29: 46006.644 | BC29: -2827 | BD29: (27642) 충청북도 음성군 금왕읍 금일로 259 (주)대승아이앤피 | BE29: 광고>쇼핑검색광고>쇼핑몰상품형
A30: 2025121570564721 | B30: 2025121583283841 | C30: 당일발송 | E30: 택배,등기,소포 | F30: 택배,등기,소포 | G30: 로젠택배 | I30: 46007.334 | J30: 스마트스토어 | K30: 이슬 | L30: rhdr***** | M30: 이슬 | N30: 발송대기 | O30: 신규주문 | P30: PC | Q30: 46006.591 | R30: 5994906898 | S30: 따사룸 층간소음 퍼즐매트 100x100x2.5 대형 바닐라아이보리 아기 유아 거실 놀이방 복도 | T30: 조합형옵션상품 | U30: 비대상 | V30: ⛄홀리데이⛄제품 타입: 퍼즐매트 / 색상: 바닐라아이보리 / (두께)사이즈: (25mm) 100x100 1장 | X30: 18 | Y30: 0 | Z30: 23000 | AA30: 91800 | AB30: 91800 | AC30: 322200 | AF30: 46008 | AI30: 무료 | AJ30: 2025121524741692 | AK30: 무료 | AL30: 0 | AM30: 0 | AN30: 0 | AO30: A | AP30: 010-5424-9068 | AR30: 경기도 여주시 산북면 상품로 72 (산북면) 1층 102호 | AS30: 경기도 여주시 산북면 상품로 72 (산북면) | AT30: 1층 102호 | AU30: 010-5424-9068 | AV30: 12603 | AX30: 무통장입금 | AY30: -6444 | AZ30: 304061 | BB30: 46006.588 | BC30: -11695 | BD30: (27642) 충청북도 음성군 금왕읍 금일로 259 (주)대승아이앤피 | BE30: 네이버플러스스토어검색>광고
A31: 2025121566863231 | B31: 2025121580886041 | C31: 당일발송 | E31: 택배,등기,소포 | F31: 택배,등기,소포 | G31: 로젠택배 | I31: 46007.334 | J31: 스마트스토어 | K31: 김영국 | L31: dudr***** | M31: 김영국 | N31: 발송대기 | O31: 신규주문 | P31: MOBILE | Q31: 46006.538 | R31: 6092903705 | S31: 따사룸 층간소음매트 아기 유아 거실 롤매트 놀이방 셀프시공 마블아이보리 70x50x1.7cm | T31: 조합형옵션상품 | U31: 비대상 | V31: ⛄홀리데이⛄디자인: 🔥HOT🔥퓨어아이보리 / 두께 / 폭: 1.7cm/140cm / 길이: 400cm | X31: 1 | Y31: 134900 | Z31: 19800 | AA31: 9100 | AB31: 9100 | AC31: 145600 | AD31: 10만원 이상 / 2롤 이상 구매 시 → 실리콘 테이프 20m 증정! | AF31: 46008 | AI31: 무료 | AJ31: 2025121524288171 | AK31: 무료 | AL31: 0 | AM31: 0 | AN31: 0 | AO31: A | AP31: 010-9080-1385 | AR31: 전북특별자치도 전주시 덕진구 세병로 130 (송천동2가, 에코시티 데시앙 네스트) 802동1403호 | AS31: 전북특별자치도 전주시 덕진구 세병로 130 (송천동2가, 에코시티 데시앙 네스트) | AT31: 802동1403호 | AU31: 010-9080-1385 | AV31: 55150 | AX31: 신용카드 간편결제 | AY31: -5824 | AZ31: 134491 | BB31: 46006.538 | BC31: -5285 | BD31: (27642) 충청북도 음성군 금왕읍 금일로 259 (주)대승아이앤피 | BE31: 마이쇼핑>장바구니(네이버쇼핑)
A32: 2025121566863221 | B32: 2025121580886041 | C32: 당일발송 | E32: 택배,등기,소포 | F32: 택배,등기,소포 | G32: 로젠택배 | I32: 46007.334 | J32: 스마트스토어 | K32: 김영국 | L32: dudr***** | M32: 김영국 | N32: 발송대기 | O32: 신규주문 | P32: MOBILE | Q32: 46006.538 | R32: 6092903705 | S32: 따사룸 층간소음매트 아기 유아 거실 롤매트 놀이방 셀프시공 마블아이보리 70x50x1.7cm | T32: 조합형옵션상품 | U32: 비대상 | V32: ⛄홀리데이⛄디자인: 🔥HOT🔥퓨어아이보리 / 두께 / 폭: 1.7cm/140cm / 길이: 250cm | X32: 1 | Y32: 80300 | Z32: 19800 | AA32: 10100 | AB32: 10100 | AC32: 90000 | AD32: 10만원 이상 / 2롤 이상 구매 시 → 실리콘 테이프 20m 증정! | AF32: 46008 | AI32: 무료 | AJ32: 2025121524288171 | AK32: 무료 | AL32: 0 | AM32: 0 | AN32: 0 | AO32: A | AP32: 010-9080-1385 | AR32: 전북특별자치도 전주시 덕진구 세병로 130 (송천동2가, 에코시티 데시앙 네스트) 802동1403호 | AS32: 전북특별자치도 전주시 덕진구 세병로 130 (송천동2가, 에코시티 데시앙 네스트) | AT32: 802동1403호 | AU32: 010-9080-1385 | AV32: 55150 | AX32: 신용카드 간편결제 | AY32: -3600 | AZ32: 83133 | BB32: 46006.538 | BC32: -3267 | BD32: (27642) 충청북도 음성군 금왕읍 금일로 259 (주)대승아이앤피 | BE32: 마이쇼핑>장바구니(네이버쇼핑)
A33: 2025121566863211 | B33: 2025121580886041 | C33: 당일발송 | E33: 택배,등기,소포 | F33: 택배,등기,소포 | G33: 로젠택배 | I33: 46007.334 | J33: 스마트스토어 | K33: 김영국 | L33: dudr***** | M33: 김영국 | N33: 발송대기 | O33: 신규주문 | P33: MOBILE | Q33: 46006.538 | R33: 6092903705 | S33: 따사룸 층간소음매트 아기 유아 거실 롤매트 놀이방 셀프시공 마블아이보리 70x50x1.7cm | T33: 조합형옵션상품 | U33: 비대상 | V33: ⛄홀리데이⛄디자인: 🔥HOT🔥퓨어아이보리 / 두께 / 폭: 1.7cm/120cm / 길이: 800cm | X33: 1 | Y33: 234100 | Z33: 19800 | AA33: 9100 | AB33: 9100 | AC33: 244800 | AD33: 10만원 이상 / 2롤 이상 구매 시 → 실리콘 테이프 20m 증정! | AF33: 46008 | AI33: 무료 | AJ33: 2025121524288171 | AK33: 무료 | AL33: 0 | AM33: 0 | AN33: 0 | AO33: A | AP33: 010-9080-1385 | AR33: 전북특별자치도 전주시 덕진구 세병로 130 (송천동2가, 에코시티 데시앙 네스트) 802동1403호 | AS33: 전북특별자치도 전주시 덕진구 세병로 130 (송천동2가, 에코시티 데시앙 네스트) | AT33: 802동1403호 | AU33: 010-9080-1385 | AV33: 55150 | AX33: 신용카드 간편결제 | AY33: -9792 | AZ33: 226122 | BB33: 46006.538 | BC33: -8886 | BD33: (27642) 충청북도 음성군 금왕읍 금일로 259 (주)대승아이앤피 | BE33: 마이쇼핑>장바구니(네이버쇼핑)
A34: 2025121566427551 | B34: 2025121580602371 | C34: 당일발송 | E34: 택배,등기,소포 | F34: 택배,등기,소포 | G34: 로젠택배 | I34: 46007.334 | J34: 스마트스토어 | K34: 김득봉 | L34: eodn***** | M34: 김득봉 | N34: 발송대기 | O34: 신규주문 | P34: MOBILE | Q34: 46006.532 | R34: 5994906898 | S34: 따사룸 층간소음 퍼즐매트 100x100x2.5 대형 바닐라아이보리 아기 유아 거실 놀이방 복도 | T34: 조합형옵션상품 | U34: 비대상 | V34: ⛄홀리데이⛄제품 타입: 퍼즐매트 / 색상: 라이트그레이 / (두께)사이즈: (25mm) 100x100 1장 | X34: 3 | Y34: 0 | Z34: 23000 | AA34: 16300 | AB34: 16300 | AC34: 52700 | AF34: 46008 | AI34: 무료 | AJ34: 2025121524234518 | AK34: 무료 | AL34: 0 | AM34: 0 | AN34: 0 | AO34: A | AP34: 010-4686-0482 | AR34: 전라남도 해남군 화원면 금평길 54 (화원면, 궁전빌라) 404호 | AS34: 전라남도 해남군 화원면 금평길 54 (화원면, 궁전빌라) | AT34: 404호 | AU34: 010-4686-0482 | AV34: 59002 | AX34: 머니결제 | AY34: -2108 | AZ34: 48679 | BB34: 46006.532 | BC34: -1913 | BD34: (27642) 충청북도 음성군 금왕읍 금일로 259 (주)대승아이앤피 | BE34: 검색>쇼핑검색(네이버쇼핑)
A35: 2025121564450851 | B35: 2025121579285611 | C35: 당일발송 | E35: 택배,등기,소포 | F35: 택배,등기,소포 | G35: 로젠택배 | I35: 46007.334 | J35: 스마트스토어 | K35: 김규동 | L35: ehd3*** | M35: 김규동 | N35: 발송대기 | O35: 신규주문 | P35: MOBILE | Q35: 46006.504 | R35: 6092903705 | S35: [G001]20m | T35: 추가구성상품 | U35: 비대상 | V35: [G001]매트접합용 실리콘테이프: [G001]20m | W35: A | X35: 1 | Y35: 0 | Z35: 7900 | AA35: 0 | AB35: 0 | AC35: 7900 | AD35: 10만원 이상 / 2롤 이상 구매 시 → 실리콘 테이프 20m 증정! | AF35: 46008 | AI35: 무료 | AJ35: 2025121523984959 | AK35: 무료 | AL35: 0 | AM35: 0 | AN35: 0 | AO35: A | AP35: 010-7220-3846 | AR35: 부산광역시 금정구 중앙대로1685번길 24 (부곡동, 경남한신아파트) 101동 1201호 | AS35: 부산광역시 금정구 중앙대로1685번길 24 (부곡동, 경남한신아파트) | AT35: 101동 1201호 | AU35: 010-7220-3846 | AV35: 46277 | AW35: 문앞에 놔주세요. | AX35: 신용카드 간편결제 | AY35: -158 | AZ35: 7457 | BB35: 46006.504 | BC35: -285 | BD35: (27642) 충청북도 음성군 금왕읍 금일로 259 (주)대승아이앤피 | BE35: 광고>쇼핑검색광고>쇼핑몰상품형>상품찜
A36: 2025121564450841 | B36: 2025121579285611 | C36: 당일발송 | E36: 택배,등기,소포 | F36: 택배,등기,소포 | G36: 로젠택배 | I36: 46007.334 | J36: 스마트스토어 | K36: 김규동 | L36: ehd3*** | M36: 김규동 | N36: 발송대기 | O36: 신규주문 | P36: MOBILE | Q36: 46006.504 | R36: 6092903705 | S36: 따사룸 층간소음매트 아기 유아 거실 롤매트 놀이방 셀프시공 마블아이보리 70x50x1.7cm | T36: 조합형옵션상품 | U36: 비대상 | V36: ⛄홀리데이⛄디자인: 🔥HOT🔥퓨어아이보리 / 두께 / 폭: 2.2cm/120cm / 길이: 250cm | X36: 1 | Y36: 93800 | Z36: 19800 | AA36: 19550 | AB36: 19550 | AC36: 94050 | AD36: 10만원 이상 / 2롤 이상 구매 시 → 실리콘 테이프 20m 증정! | AF36: 46008 | AI36: 무료 | AJ36: 2025121523984959 | AK36: 무료 | AL36: 0 | AM36: 0 | AN36: 0 | AO36: A | AP36: 010-7220-3846 | AR36: 부산광역시 금정구 중앙대로1685번길 24 (부곡동, 경남한신아파트) 101동 1201호 | AS36: 부산광역시 금정구 중앙대로1685번길 24 (부곡동, 경남한신아파트) | AT36: 101동 1201호 | AU36: 010-7220-3846 | AV36: 46277 | AW36: 문앞에 놔주세요. | AX36: 신용카드 간편결제 | AY36: -1881 | AZ36: 88756 | BB36: 46006.504 | BC36: -3413 | BD36: (27642) 충청북도 음성군 금왕읍 금일로 259 (주)대승아이앤피 | BE36: 광고>쇼핑검색광고>쇼핑몰상품형>상품찜
A37: 2025121564450831 | B37: 2025121579285611 | C37: 당일발송 | E37: 택배,등기,소포 | F37: 택배,등기,소포 | G37: 로젠택배 | I37: 46007.334 | J37: 스마트스토어 | K37: 김규동 | L37: ehd3*** | M37: 김규동 | N37: 발송대기 | O37: 신규주문 | P37: MOBILE | Q37: 46006.504 | R37: 6092903705 | S37: 따사룸 층간소음매트 아기 유아 거실 롤매트 놀이방 셀프시공 마블아이보리 70x50x1.7cm | T37: 조합형옵션상품 | U37: 비대상 | V37: ⛄홀리데이⛄디자인: 🔥HOT🔥퓨어아이보리 / 두께 / 폭: 2.2cm/110cm / 길이: 250cm | X37: 1 | Y37: 84800 | Z37: 19800 | AA37: 10100 | AB37: 10100 | AC37: 94500 | AD37: 10만원 이상 / 2롤 이상 구매 시 → 실리콘 테이프 20m 증정! | AF37: 46008 | AI37: 무료 | AJ37: 2025121523984959 | AK37: 무료 | AL37: 0 | AM37: 0 | AN37: 0 | AO37: A | AP37: 010-7220-3846 | AR37: 부산광역시 금정구 중앙대로1685번길 24 (부곡동, 경남한신아파트) 101동 1201호 | AS37: 부산광역시 금정구 중앙대로1685번길 24 (부곡동, 경남한신아파트) | AT37: 101동 1201호 | AU37: 010-7220-3846 | AV37: 46277 | AW37: 문앞에 놔주세요. | AX37: 신용카드 간편결제 | AY37: -1890 | AZ37: 89181 | BB37: 46006.504 | BC37: -3429 | BD37: (27642) 충청북도 음성군 금왕읍 금일로 259 (주)대승아이앤피 | BE37: 광고>쇼핑검색광고>쇼핑몰상품형>상품찜
A38: 2025121559970241 | B38: 2025121576342871 | C38: 당일발송 | E38: 택배,등기,소포 | F38: 택배,등기,소포 | G38: 로젠택배 | I38: 46007.334 | J38: 스마트스토어 | K38: 이좌훈 | L38: whkg**** | M38: 이좌훈 | N38: 발송대기 | O38: 신규주문 | P38: PC | Q38: 46006.45 | R38: 5994906898 | S38: 따사룸 층간소음 퍼즐매트 100x100x2.5 대형 바닐라아이보리 아기 유아 거실 놀이방 복도 | T38: 조합형옵션상품 | U38: 비대상 | V38: ⛄홀리데이⛄제품 타입: ✨퍼즐매트 PLUS+✨ / 색상: 크림그레이 / (두께)사이즈: (25mm) 50x50 4장 | X38: 10 | Y38: 4900 | Z38: 23000 | AA38: 51000 | AB38: 51000 | AC38: 228000 | AF38: 46008 | AI38: 무료 | AJ38: 2025121523438219 | AK38: 무료 | AL38: 0 | AM38: 0 | AN38: 0 | AO38: A | AP38: 010-5023-9290 | AR38: 경기도 평택시 신장로 55 (신장동) 사서함 309-25호 (공군 1887부대) | AS38: 경기도 평택시 신장로 55 (신장동) | AT38: 사서함 309-25호 (공군 1887부대) | AU38: 010-5023-9290 | AV38: 17759 | AX38: 신용카드 | AY38: -4560 | AZ38: 215164 | BB38: 46006.45 | BC38: -8276 | BD38: (27642) 충청북도 음성군 금왕읍 금일로 259 (주)대승아이앤피 | BE38: 광고>쇼핑검색광고>쇼핑몰상품형
A39: 2025121559970231 | B39: 2025121576342871 | C39: 당일발송 | E39: 택배,등기,소포 | F39: 택배,등기,소포 | G39: 로젠택배 | I39: 46007.334 | J39: 스마트스토어 | K39: 이좌훈 | L39: whkg**** | M39: 이좌훈 | N39: 발송대기 | O39: 신규주문 | P39: PC | Q39: 46006.45 | R39: 5994906898 | S39: 따사룸 층간소음 퍼즐매트 100x100x2.5 대형 바닐라아이보리 아기 유아 거실 놀이방 복도 | T39: 조합형옵션상품 | U39: 비대상 | V39: ⛄홀리데이⛄제품 타입: ✨퍼즐매트 PLUS+✨ / 색상: 크림그레이 / (두께)사이즈: (25mm) 100x100 1장 | X39: 20 | Y39: 4900 | Z39: 23000 | AA39: 102000 | AB39: 102000 | AC39: 456000 | AF39: 46008 | AI39: 무료 | AJ39: 2025121523438219 | AK39: 무료 | AL39: 0 | AM39: 0 | AN39: 0 | AO39: A | AP39: 010-5023-9290 | AR39: 경기도 평택시 신장로 55 (신장동) 사서함 309-25호 (공군 1887부대) | AS39: 경기도 평택시 신장로 55 (신장동) | AT39: 사서함 309-25호 (공군 1887부대) | AU39: 010-5023-9290 | AV39: 17759 | AX39: 신용카드 | AY39: -9120 | AZ39: 430328 | BB39: 46006.45 | BC39: -16552 | BD39: (27642) 충청북도 음성군 금왕읍 금일로 259 (주)대승아이앤피 | BE39: 광고>쇼핑검색광고>쇼핑몰상품형
A40: 2025121559364301 | B40: 2025121575938591 | C40: 당일발송 | E40: 택배,등기,소포 | F40: 택배,등기,소포 | G40: 로젠택배 | I40: 46007.334 | J40: 스마트스토어 | K40: 이동하 | L40: crew************** | M40: 이동하 | N40: 발송대기 | O40: 신규주문 | P40: MOBILE | Q40: 46006.443 | R40: 6092903705 | S40: 따사룸 층간소음매트 아기 유아 거실 롤매트 놀이방 셀프시공 마블아이보리 70x50x1.7cm | T40: 조합형옵션상품 | U40: 비대상 | V40: ⛄홀리데이⛄디자인: 🏆BEST🏆마블아이보리 / 두께 / 폭: 1.7cm/120cm / 길이: 500cm | X40: 2 | Y40: 142300 | Z40: 19800 | AA40: 18200 | AB40: 18200 | AC40: 306000 | AD40: 10만원 이상 / 2롤 이상 구매 시 → 실리콘 테이프 20m 증정! | AF40: 46008 | AI40: 무료 | AJ40: 2025121523360408 | AK40: 무료 | AL40: 0 | AM40: 0 | AN40: 0 | AO40: A | AP40: 010-8969-7278 | AR40: 인천광역시 연수구 센트럴로 194 (송도동, 더샵 센트럴파크2) 202동 2405호 | AS40: 인천광역시 연수구 센트럴로 194 (송도동, 더샵 센트럴파크2) | AT40: 202동 2405호 | AU40: 010-8969-7278 | AV40: 22003 | AX40: 신용카드 | AY40: -12240 | AZ40: 282653 | BB40: 46006.442 | BC40: -11107 | BD40: (27642) 충청북도 음성군 금왕읍 금일로 259 (주)대승아이앤피 | BE40: 알림>상품문의답변
...

Sheet 송장화1
A1: 상품주문번호 | B1: 수취인명 | C1: 운임타입 | D1: 송장수량 | E1: 디자인 | F1: 길이 | G1: 수량 | H1: 추가상품1 | I1: 배송메세지 | J1: 합포장 | K1: 비고 | L1: 주문하신분 핸드폰 | M1: 받는분 핸드폰 | N1: 우편번호 | O1: 받는분 주소 | P1: 주문자명 | Q1: 실제결제금액
A2: =발송처리!A2 -> 2025121699647131 | B2: =발송처리!M2 -> 이주현 | E2: =VLOOKUP(발송처리!V2,'상품DB(수정x)'!B:E,2,0) -> (140)17T퓨어아이보리 | F2: =VLOOKUP(발송처리!V2,'상품DB(수정x)'!B:E,4,0) -> 8m | G2: =발송처리!X2 -> 1 | I2: =발송처리!AW2 -> 문 앞에 놓아주세요 | K2: =IF(LEFT(E2,1)="2","",IF(LEFT(E2,1)="4","",IF(Q2>=500000,"★증정★테이프20mx2",IF(Q2>=95000,"★증정★테이프20mx1","")))) -> ★증정★테이프20mx1 | L2: =발송처리!AU2 -> 010-6412-7957 | M2: =발송처리!AP2 -> 010-6412-7957 | N2: =발송처리!AV2 -> 10562 | O2: =발송처리!AR2 -> 경기도 고양시 덕양구 원흥1로 31 (원흥동, 고양삼송엘에이치10단지아파트) 1004-502 | P2: =발송처리!K2 -> 이주현 | Q2: =발송처리!AC2 -> 262080
A3: =발송처리!A3 -> 2025121699509111 | B3: =발송처리!M3 -> 김기민 | E3: =VLOOKUP(발송처리!V3,'상품DB(수정x)'!B:E,2,0) -> (110)15TPE딜라이트우드 | F3: =VLOOKUP(발송처리!V3,'상품DB(수정x)'!B:E,4,0) -> 2m | G3: =발송처리!X3 -> 1 | I3: =발송처리!AW3 -> 0 | K3: =IF(LEFT(E3,1)="2","",IF(LEFT(E3,1)="4","",IF(Q3>=500000,"★증정★테이프20mx2",IF(Q3>=95000,"★증정★테이프20mx1","")))) | L3: =발송처리!AU3 -> 010-2914-9937 | M3: =발송처리!AP3 -> 010-2914-9937 | N3: =발송처리!AV3 -> 10811 | O3: =발송처리!AR3 -> 경기도 파주시 문산읍 통일로 1750 (문산읍, 문산어울림) 문산어울림 105동 501호 | P3: =발송처리!K3 -> 김기민 | Q3: =발송처리!AC3 -> 32560
A4: =발송처리!A4 -> 2025121698258721 | B4: =발송처리!M4 -> 이미라 | E4: =VLOOKUP(발송처리!V4,'상품DB(수정x)'!B:E,2,0) -> 패브릭트윈 XL [240x140 12T] | F4: =VLOOKUP(발송처리!V4,'상품DB(수정x)'!B:E,4,0) -> XL | G4: =발송처리!X4 -> 1 | I4: =발송처리!AW4 -> 배송 전 미리 연락해 주세요 | K4: =IF(LEFT(E4,1)="2","",IF(LEFT(E4,1)="4","",IF(Q4>=500000,"★증정★테이프20mx2",IF(Q4>=95000,"★증정★테이프20mx1","")))) -> ★증정★테이프20mx1 | L4: =발송처리!AU4 -> 010-7184-2910 | M4: =발송처리!AP4 -> 010-7184-2910 | N4: =발송처리!AV4 -> 18127 | O4: =발송처리!AR4 -> 경기도 오산시 초평중앙로 10 (탑동, 오산세교 한신더휴) 2201동 903호 | P4: =발송처리!K4 -> 김인혜 | Q4: =발송처리!AC4 -> 117170
A5: =발송처리!A5 -> 2025121696405561 | B5: =발송처리!M5 -> 전준하 | E5: =VLOOKUP(발송처리!V5,'상품DB(수정x)'!B:E,2,0) -> (140)17T퓨어아이보리 | F5: =VLOOKUP(발송처리!V5,'상품DB(수정x)'!B:E,4,0) -> 8m | G5: =발송처리!X5 -> 1 | I5: =발송처리!AW5 -> 물품 잘 확인해서 보내주세요. 배송시 문자주시고 문앞에 놓아주세요. 감사합니다. | K5: =IF(LEFT(E5,1)="2","",IF(LEFT(E5,1)="4","",IF(Q5>=500000,"★증정★테이프20mx2",IF(Q5>=95000,"★증정★테이프20mx1","")))) -> ★증정★테이프20mx1 | L5: =발송처리!AU5 -> 010-5153-1054 | M5: =발송처리!AP5 -> 010-5153-1054 | N5: =발송처리!AV5 -> 18405 | O5: =발송처리!AR5 -> 경기도 화성시 병점3로 117 (병점동, 안화동마을주공9단지) 901동 1605호 | P5: =발송처리!K5 -> 전준하 | Q5: =발송처리!AC5 -> 262080
A6: =발송처리!A6 -> 2025121695559201 | B6: =발송처리!M6 -> 나병준 | E6: =VLOOKUP(발송처리!V6,'상품DB(수정x)'!B:E,2,0) -> 25T(퍼즐)아이보리(50) | F6: =VLOOKUP(발송처리!V6,'상품DB(수정x)'!B:E,4,0) | G6: =발송처리!X6 -> 6 | I6: =발송처리!AW6 -> 0 | K6: =IF(LEFT(E6,1)="2","",IF(LEFT(E6,1)="4","",IF(Q6>=500000,"★증정★테이프20mx2",IF(Q6>=95000,"★증정★테이프20mx1","")))) | L6: =발송처리!AU6 -> 010-9174-1121 | M6: =발송처리!AP6 -> 010-9174-1121 | N6: =발송처리!AV6 -> 16823 | O6: =발송처리!AR6 -> 경기도 용인시 수지구 손곡로 82 (동천동, 수진마을써니벨리아파트) 106동 506호 | P6: =발송처리!K6 -> 나병준 | Q6: =발송처리!AC6 -> 106400
A7: =발송처리!A7 -> 2025121594828291 | B7: =발송처리!M7 -> 나대남 | E7: =VLOOKUP(발송처리!V7,'상품DB(수정x)'!B:E,2,0) -> ★판매★테이프20m | F7: =VLOOKUP(발송처리!V7,'상품DB(수정x)'!B:E,4,0) -> 0 | G7: =발송처리!X7 -> 1 | I7: =발송처리!AW7 -> 배송 전 미리 연락해 주세요 | K7: =IF(LEFT(E7,1)="2","",IF(LEFT(E7,1)="4","",IF(Q7>=500000,"★증정★테이프20mx2",IF(Q7>=95000,"★증정★테이프20mx1","")))) | L7: =발송처리!AU7 -> 010-8965-2389 | M7: =발송처리!AP7 -> 0502-3214-2132 | N7: =발송처리!AV7 -> 01014 | O7: =발송처리!AR7 -> 서울특별시 강북구 4.19로13길 9 (수유동, 우이블루빌) 402호 | P7: =발송처리!K7 -> 나대남 | Q7: =발송처리!AC7 -> 7900
A8: =발송처리!A8 -> 2025121594828281 | B8: =발송처리!M8 -> 나대남 | E8: =VLOOKUP(발송처리!V8,'상품DB(수정x)'!B:E,2,0) -> (110)17T마블아이보리 | F8: =VLOOKUP(발송처리!V8,'상품DB(수정x)'!B:E,4,0) -> 5.5m | G8: =발송처리!X8 -> 1 | I8: =발송처리!AW8 -> 배송 전 미리 연락해 주세요 | K8: =IF(LEFT(E8,1)="2","",IF(LEFT(E8,1)="4","",IF(Q8>=500000,"★증정★테이프20mx2",IF(Q8>=95000,"★증정★테이프20mx1","")))) -> ★증정★테이프20mx1 | L8: =발송처리!AU8 -> 010-8965-2389 | M8: =발송처리!AP8 -> 0502-3214-2132 | N8: =발송처리!AV8 -> 01014 | O8: =발송처리!AR8 -> 서울특별시 강북구 4.19로13길 9 (수유동, 우이블루빌) 402호 | P8: =발송처리!K8 -> 나대남 | Q8: =발송처리!AC8 -> 151800
A9: =발송처리!A9 -> 2025121594828271 | B9: =발송처리!M9 -> 나대남 | E9: =VLOOKUP(발송처리!V9,'상품DB(수정x)'!B:E,2,0) -> (110)17T마블아이보리 | F9: =VLOOKUP(발송처리!V9,'상품DB(수정x)'!B:E,4,0) -> 5m | G9: =발송처리!X9 -> 2 | I9: =발송처리!AW9 -> 배송 전 미리 연락해 주세요 | K9: =IF(LEFT(E9,1)="2","",IF(LEFT(E9,1)="4","",IF(Q9>=500000,"★증정★테이프20mx2",IF(Q9>=95000,"★증정★테이프20mx1","")))) -> ★증정★테이프20mx1 | L9: =발송처리!AU9 -> 010-8965-2389 | M9: =발송처리!AP9 -> 0502-3214-2132 | N9: =발송처리!AV9 -> 01014 | O9: =발송처리!AR9 -> 서울특별시 강북구 4.19로13길 9 (수유동, 우이블루빌) 402호 | P9: =발송처리!K9 -> 나대남 | Q9: =발송처리!AC9 -> 248400
A10: =발송처리!A10 -> 2025121594828261 | B10: =발송처리!M10 -> 나대남 | E10: =VLOOKUP(발송처리!V10,'상품DB(수정x)'!B:E,2,0) -> (120)17T마블아이보리 | F10: =VLOOKUP(발송처리!V10,'상품DB(수정x)'!B:E,4,0) -> 3m | G10: =발송처리!X10 -> 1 | I10: =발송처리!AW10 -> 배송 전 미리 연락해 주세요 | K10: =IF(LEFT(E10,1)="2","",IF(LEFT(E10,1)="4","",IF(Q10>=500000,"★증정★테이프20mx2",IF(Q10>=95000,"★증정★테이프20mx1","")))) | L10: =발송처리!AU10 -> 010-8965-2389 | M10: =발송처리!AP10 -> 0502-3214-2132 | N10: =발송처리!AV10 -> 01014 | O10: =발송처리!AR10 -> 서울특별시 강북구 4.19로13길 9 (수유동, 우이블루빌) 402호 | P10: =발송처리!K10 -> 나대남 | Q10: =발송처리!AC10 -> 91800
A11: =발송처리!A11 -> 2025121594828251 | B11: =발송처리!M11 -> 나대남 | E11: =VLOOKUP(발송처리!V11,'상품DB(수정x)'!B:E,2,0) -> (120)17T마블아이보리 | F11: =VLOOKUP(발송처리!V11,'상품DB(수정x)'!B:E,4,0) -> 2m | G11: =발송처리!X11 -> 1 | I11: =발송처리!AW11 -> 배송 전 미리 연락해 주세요 | K11: =IF(LEFT(E11,1)="2","",IF(LEFT(E11,1)="4","",IF(Q11>=500000,"★증정★테이프20mx2",IF(Q11>=95000,"★증정★테이프20mx1","")))) | L11: =발송처리!AU11 -> 010-8965-2389 | M11: =발송처리!AP11 -> 0502-3214-2132 | N11: =발송처리!AV11 -> 01014 | O11: =발송처리!AR11 -> 서울특별시 강북구 4.19로13길 9 (수유동, 우이블루빌) 402호 | P11: =발송처리!K11 -> 나대남 | Q11: =발송처리!AC11 -> 59200
A12: =발송처리!A12 -> 2025121594230371 | B12: =발송처리!M12 -> 최규철 | E12: =VLOOKUP(발송처리!V12,'상품DB(수정x)'!B:E,2,0) -> (140)6T소프트그레이 | F12: =VLOOKUP(발송처리!V12,'상품DB(수정x)'!B:E,4,0) -> 0.5m | G12: =발송처리!X12 -> 4 | I12: =발송처리!AW12 -> 0 | K12: =IF(LEFT(E12,1)="2","",IF(LEFT(E12,1)="4","",IF(Q12>=500000,"★증정★테이프20mx2",IF(Q12>=95000,"★증정★테이프20mx1","")))) | L12: =발송처리!AU12 -> 010-8823-9437 | M12: =발송처리!AP12 -> 010-8823-9437 | N12: =발송처리!AV12 -> 37107 | O12: =발송처리!AR12 -> 경상북도 상주시 이안면 양범안룡길 80 (이안면) 양범교회 | P12: =발송처리!K12 -> 최규철 | Q12: =발송처리!AC12 -> 52800
A13: =발송처리!A13 -> 2025121594072441 | B13: =발송처리!M13 -> 한정우 | E13: =VLOOKUP(발송처리!V13,'상품DB(수정x)'!B:E,2,0) -> 플러스♥25T아이(100) | F13: =VLOOKUP(발송처리!V13,'상품DB(수정x)'!B:E,4,0) -> 0 | G13: =발송처리!X13 -> 1 | I13: =발송처리!AW13 -> 0 | K13: =IF(LEFT(E13,1)="2","",IF(LEFT(E13,1)="4","",IF(Q13>=500000,"★증정★테이프20mx2",IF(Q13>=95000,"★증정★테이프20mx1","")))) | L13: =발송처리!AU13 -> 010-9524-9234 | M13: =발송처리!AP13 -> 010-9524-9234 | N13: =발송처리!AV13 -> 07520 | O13: =발송처리!AR13 -> 서울특별시 강서구 양천로 177 (마곡동, 가양하수처리장직원아파트) 2동 206호 | P13: =발송처리!K13 -> 한정우 | Q13: =발송처리!AC13 -> 22800
... A43: =발송처리!A43 -> 2025121556791061 | B43: =발송처리!M43 -> 권하람 | E43: =VLOOKUP(발송처리!V43,'상품DB(수정x)'!B:E,2,0) -> (140)17T퓨어아이보리 | F43: =VLOOKUP(발송처리!V43,'상품DB(수정x)'!B:E,4,0) -> 7m | G43: =발송처리!X43 -> 1 | I43: =발송처리!AW43 -> 0 | K43: =IF(LEFT(E43,1)="2","",IF(LEFT(E43,1)="4","",IF(Q43>=500000,"★증정★테이프20mx2",IF(Q43>=95000,"★증정★테이프20mx1","")))) -> ★증정★테이프20mx1 | L43: =발송처리!AU43 -> 010-3901-6006 | M43: =발송처리!AP43 -> 010-3901-6006 | N43: =발송처리!AV43 -> 42810 | O43: =발송처리!AR43 -> 대구광역시 달서구 상인서로 85 (상인동, 상인동방현대아파트) 103동 1106호 | P43: =발송처리!K43 -> 권하람 | Q43: =발송처리!AC43 -> 229320
A44: 2025121555824751 | B44: 박주영 | E44: ★판매★테이프20m | F44: 0 | G44: 1 | I44: 0 | L44: 010-2794-5247 | M44: 010-2794-5247 | N44: 10522 | O44: 경기도 고양시 덕양구 소원로 47 (행신동, 무원마을6단지아파트) 611동1204호 | P44: 박주영 | Q44: 7900
A45: 2025121555824741 | B45: 박주영 | E45: #N/A | F45: #N/A | G45: 3 | I45: 0 | K45: #N/A | L45: 010-2794-5247 | M45: 010-2794-5247 | N45: 10522 | O45: 경기도 고양시 덕양구 소원로 47 (행신동, 무원마을6단지아파트) 611동1204호 | P45: 박주영 | Q45: 371790
A46: 2025121554711191 | B46: 김유진 | E46: 25T(퍼즐)아이보리(100) | G46: 5 | I46: 0 | L46: 010-9374-1270 | M46: 010-9374-1270 | N46: 42483 | O46: 대구광역시 남구 대명로14길 60 (대명동) 102동 302호(대명역센트럴엘리프) | P46: 김유진 | Q46: 89500
A47: 2025121553621961 | B47: 문혜인 | E47: 40T(퍼즐)아이보리(100) | G47: 18 | I47: 0 | L47: 010-9809-9970 | M47: 0502-2812-5266 | N47: 03768 | O47: 서울특별시 서대문구 북아현로1가길 20 (북아현동, e편한세상신촌 1단지) 106-201 | P47: 문혜인 | Q47: 473400
A48: 2025121553621951 | B48: 문혜인 | E48: 40T(퍼즐)아이보리(50) | G48: 1 | I48: 0 | L48: 010-9809-9970 | M48: 0502-2812-5266 | N48: 03768 | O48: 서울특별시 서대문구 북아현로1가길 20 (북아현동, e편한세상신촌 1단지) 106-201 | P48: 문혜인 | Q48: 25300
A49: 2025121553369531 | B49: 이민수 | E49: (110)17T마블아이보리 | F49: 4.5m | G49: 2 | I49: 0 | K49: ★증정★테이프20mx1 | L49: 010-9924-5053 | M49: 010-9924-5053 | N49: 42793 | O49: 대구광역시 달서구 상화북로 159 (상인동, 산호아파트) 7동202호 | P49: 이민수 | Q49: 248400
A50: 2025121553369521 | B50: 이민수 | E50: (70)17T마블아이보리 | F50: 4.5m | G50: 1 | I50: 0 | K50: ★증정★테이프20mx1 | L50: 010-9924-5053 | M50: 010-9924-5053 | N50: 42793 | O50: 대구광역시 달서구 상화북로 159 (상인동, 산호아파트) 7동202호 | P50: 이민수 | Q50: 96300
A51: 2025121551344631 | B51: 기선경 | E51: #N/A | F51: #N/A | G51: 1 | I51: 문 앞에 놓아주세요 | K51: #N/A | L51: 010-5013-8717 | M51: 010-5013-8717 | N51: 03468 | O51: 서울특별시 은평구 응암로20길 22 (응암동) 3층 나호 | P51: 기선경 | Q51: 7900
A52: 2025121551344621 | B52: 기선경 | E52: #N/A | F52: #N/A | G52: 1 | I52: 문 앞에 놓아주세요 | K52: #N/A | L52: 010-5013-8717 | M52: 010-5013-8717 | N52: 03468 | O52: 서울특별시 은평구 응암로20길 22 (응암동) 3층 나호 | P52: 기선경 | Q52: 64800
A53: 2025121551344611 | B53: 기선경 | E53: #N/A | F53: #N/A | G53: 1 | I53: 문 앞에 놓아주세요 | K53: #N/A | L53: 010-5013-8717 | M53: 010-5013-8717 | N53: 03468 | O53: 서울특별시 은평구 응암로20길 22 (응암동) 3층 나호 | P53: 기선경 | Q53: 52400
A54: 2025121550957281 | B54: 박동건 | E54: (110)22T마블아이보리 | F54: 3m | G54: 1 | I54: 현관문 앞에 놓아 주세여. 감사합니다. | K54: ★증정★테이프20mx1 | L54: 010-2631-8314 | M54: 010-2631-8314 | N54: 22231 | O54: 인천광역시 미추홀구 승학길104번길 30 (주안동, 인천주안한신휴플러스) 108동 1305호 | P54: 박동건 | Q54: 114600
A55: 2025121447448151 | B55: 류홍렬 | E55: 플러스♥25T크림그레이(50) | F55: 0 | G55: 2 | I55: 0 | L55: 010-7411-1873 | M55: 010-7411-1873 | N55: 31817 | O55: 충청남도 당진시 수청1로 51 (수청동, 호반써밋 시그니처 2차) 201동 302호 | P55: 류홍렬 | Q55: 45600
A56: 2025121447448141 | B56: 류홍렬 | E56: 플러스♥25T크림그레이(100) | F56: 0 | G56: 4 | I56: 0 | L56: 010-7411-1873 | M56: 010-7411-1873 | N56: 31817 | O56: 충청남도 당진시 수청1로 51 (수청동, 호반써밋 시그니처 2차) 201동 302호 | P56: 류홍렬 | Q56: 91200
A57: =발송처리!A57 -> 0 | B57: =발송처리!M57 -> 0 | E57: =VLOOKUP(발송처리!V57,'상품DB(수정x)'!B:E,2,0) -> #N/A | F57: =VLOOKUP(발송처리!V57,'상품DB(수정x)'!B:E,4,0) -> #N/A | G57: =발송처리!X57 -> 0 | I57: =발송처리!AW57 -> 0 | K57: =IF(LEFT(E57,1)="2","",IF(LEFT(E57,1)="4","",IF(Q57>=500000,"★증정★테이프20mx2",IF(Q57>=95000,"★증정★테이프20mx1","")))) -> #N/A | L57: =발송처리!AU57 -> 0 | M57: =발송처리!AP57 -> 0 | N57: =발송처리!AV57 -> 0 | O57: =발송처리!AR57 -> 0 | P57: =발송처리!K57 -> 0 | Q57: =발송처리!AC57 -> 0
A58: =발송처리!A58 -> 0 | B58: =발송처리!M58 -> 0 | E58: =VLOOKUP(발송처리!V58,'상품DB(수정x)'!B:E,2,0) -> #N/A | F58: =VLOOKUP(발송처리!V58,'상품DB(수정x)'!B:E,4,0) -> #N/A | G58: =발송처리!X58 -> 0 | I58: =발송처리!AW58 -> 0 | K58: =IF(LEFT(E58,1)="2","",IF(LEFT(E58,1)="4","",IF(Q58>=500000,"★증정★테이프20mx2",IF(Q58>=95000,"★증정★테이프20mx1","")))) -> #N/A | L58: =발송처리!AU58 -> 0 | M58: =발송처리!AP58 -> 0 | N58: =발송처리!AV58 -> 0 | O58: =발송처리!AR58 -> 0 | P58: =발송처리!K58 -> 0 | Q58: =발송처리!AC58 -> 0
A59: =발송처리!A59 -> 0 | B59: =발송처리!M59 -> 0 | E59: =VLOOKUP(발송처리!V59,'상품DB(수정x)'!B:E,2,0) -> #N/A | F59: =VLOOKUP(발송처리!V59,'상품DB(수정x)'!B:E,4,0) -> #N/A | G59: =발송처리!X59 -> 0 | I59: =발송처리!AW59 -> 0 | K59: =IF(LEFT(E59,1)="2","",IF(LEFT(E59,1)="4","",IF(Q59>=500000,"★증정★테이프20mx2",IF(Q59>=95000,"★증정★테이프20mx1","")))) -> #N/A | L59: =발송처리!AU59 -> 0 | M59: =발송처리!AP59 -> 0 | N59: =발송처리!AV59 -> 0 | O59: =발송처리!AR59 -> 0 | P59: =발송처리!K59 -> 0 | Q59: =발송처리!AC59 -> 0
A60: =발송처리!A60 -> 0 | B60: =발송처리!M60 -> 0 | E60: =VLOOKUP(발송처리!V60,'상품DB(수정x)'!B:E,2,0) -> #N/A | F60: =VLOOKUP(발송처리!V60,'상품DB(수정x)'!B:E,4,0) -> #N/A | G60: =발송처리!X60 -> 0 | I60: =발송처리!AW60 -> 0 | K60: =IF(LEFT(E60,1)="2","",IF(LEFT(E60,1)="4","",IF(Q60>=500000,"★증정★테이프20mx2",IF(Q60>=95000,"★증정★테이프20mx1","")))) -> #N/A | L60: =발송처리!AU60 -> 0 | M60: =발송처리!AP60 -> 0 | N60: =발송처리!AV60 -> 0 | O60: =발송처리!AR60 -> 0 | P60: =발송처리!K60 -> 0 | Q60: =발송처리!AC60 -> 0
A61: =발송처리!A61 -> 0 | B61: =발송처리!M61 -> 0 | E61: =VLOOKUP(발송처리!V61,'상품DB(수정x)'!B:E,2,0) -> #N/A | F61: =VLOOKUP(발송처리!V61,'상품DB(수정x)'!B:E,4,0) -> #N/A | G61: =발송처리!X61 -> 0 | I61: =발송처리!AW61 -> 0 | K61: =IF(LEFT(E61,1)="2","",IF(LEFT(E61,1)="4","",IF(Q61>=500000,"★증정★테이프20mx2",IF(Q61>=95000,"★증정★테이프20mx1","")))) -> #N/A | L61: =발송처리!AU61 -> 0 | M61: =발송처리!AP61 -> 0 | N61: =발송처리!AV61 -> 0 | O61: =발송처리!AR61 -> 0 | P61: =발송처리!K61 -> 0 | Q61: =발송처리!AC61 -> 0
A62: =발송처리!A62 -> 0 | B62: =발송처리!M62 -> 0 | E62: =VLOOKUP(발송처리!V62,'상품DB(수정x)'!B:E,2,0) -> #N/A | F62: =VLOOKUP(발송처리!V62,'상품DB(수정x)'!B:E,4,0) -> #N/A | G62: =발송처리!X62 -> 0 | I62: =발송처리!AW62 -> 0 | K62: =IF(LEFT(E62,1)="2","",IF(LEFT(E62,1)="4","",IF(Q62>=500000,"★증정★테이프20mx2",IF(Q62>=95000,"★증정★테이프20mx1","")))) -> #N/A | L62: =발송처리!AU62 -> 0 | M62: =발송처리!AP62 -> 0 | N62: =발송처리!AV62 -> 0 | O62: =발송처리!AR62 -> 0 | P62: =발송처리!K62 -> 0 | Q62: =발송처리!AC62 -> 0
A63: =발송처리!A63 -> 0 | B63: =발송처리!M63 -> 0 | E63: =VLOOKUP(발송처리!V63,'상품DB(수정x)'!B:E,2,0) -> #N/A | F63: =VLOOKUP(발송처리!V63,'상품DB(수정x)'!B:E,4,0) -> #N/A | G63: =발송처리!X63 -> 0 | I63: =발송처리!AW63 -> 0 | K63: =IF(LEFT(E63,1)="2","",IF(LEFT(E63,1)="4","",IF(Q63>=500000,"★증정★테이프20mx2",IF(Q63>=95000,"★증정★테이프20mx1","")))) -> #N/A | L63: =발송처리!AU63 -> 0 | M63: =발송처리!AP63 -> 0 | N63: =발송처리!AV63 -> 0 | O63: =발송처리!AR63 -> 0 | P63: =발송처리!K63 -> 0 | Q63: =발송처리!AC63 -> 0
A64: =발송처리!A64 -> 0 | B64: =발송처리!M64 -> 0 | E64: =VLOOKUP(발송처리!V64,'상품DB(수정x)'!B:E,2,0) -> #N/A | F64: =VLOOKUP(발송처리!V64,'상품DB(수정x)'!B:E,4,0) -> #N/A | G64: =발송처리!X64 -> 0 | I64: =발송처리!AW64 -> 0 | K64: =IF(LEFT(E64,1)="2","",IF(LEFT(E64,1)="4","",IF(Q64>=500000,"★증정★테이프20mx2",IF(Q64>=95000,"★증정★테이프20mx1","")))) -> #N/A | L64: =발송처리!AU64 -> 0 | M64: =발송처리!AP64 -> 0 | N64: =발송처리!AV64 -> 0 | O64: =발송처리!AR64 -> 0 | P64: =발송처리!K64 -> 0 | Q64: =발송처리!AC64 -> 0
A65: =발송처리!A65 -> 0 | B65: =발송처리!M65 -> 0 | E65: =VLOOKUP(발송처리!V65,'상품DB(수정x)'!B:E,2,0) -> #N/A | F65: =VLOOKUP(발송처리!V65,'상품DB(수정x)'!B:E,4,0) -> #N/A | G65: =발송처리!X65 -> 0 | I65: =발송처리!AW65 -> 0 | K65: =IF(LEFT(E65,1)="2","",IF(LEFT(E65,1)="4","",IF(Q65>=500000,"★증정★테이프20mx2",IF(Q65>=95000,"★증정★테이프20mx1","")))) -> #N/A | L65: =발송처리!AU65 -> 0 | M65: =발송처리!AP65 -> 0 | N65: =발송처리!AV65 -> 0 | O65: =발송처리!AR65 -> 0 | P65: =발송처리!K65 -> 0 | Q65: =발송처리!AC65 -> 0
A66: =발송처리!A66 -> 0 | B66: =발송처리!M66 -> 0 | E66: =VLOOKUP(발송처리!V66,'상품DB(수정x)'!B:E,2,0) -> #N/A | F66: =VLOOKUP(발송처리!V66,'상품DB(수정x)'!B:E,4,0) -> #N/A | G66: =발송처리!X66 -> 0 | I66: =발송처리!AW66 -> 0 | K66: =IF(LEFT(E66,1)="2","",IF(LEFT(E66,1)="4","",IF(Q66>=500000,"★증정★테이프20mx2",IF(Q66>=95000,"★증정★테이프20mx1","")))) -> #N/A | L66: =발송처리!AU66 -> 0 | M66: =발송처리!AP66 -> 0 | N66: =발송처리!AV66 -> 0 | O66: =발송처리!AR66 -> 0 | P66: =발송처리!K66 -> 0 | Q66: =발송처리!AC66 -> 0
A67: =발송처리!A67 -> 0 | B67: =발송처리!M67 -> 0 | E67: =VLOOKUP(발송처리!V67,'상품DB(수정x)'!B:E,2,0) -> #N/A | F67: =VLOOKUP(발송처리!V67,'상품DB(수정x)'!B:E,4,0) -> #N/A | G67: =발송처리!X67 -> 0 | I67: =발송처리!AW67 -> 0 | K67: =IF(LEFT(E67,1)="2","",IF(LEFT(E67,1)="4","",IF(Q67>=500000,"★증정★테이프20mx2",IF(Q67>=95000,"★증정★테이프20mx1","")))) -> #N/A | L67: =발송처리!AU67 -> 0 | M67: =발송처리!AP67 -> 0 | N67: =발송처리!AV67 -> 0 | O67: =발송처리!AR67 -> 0 | P67: =발송처리!K67 -> 0 | Q67: =발송처리!AC67 -> 0
A68: =발송처리!A68 -> 0 | B68: =발송처리!M68 -> 0 | E68: =VLOOKUP(발송처리!V68,'상품DB(수정x)'!B:E,2,0) -> #N/A | F68: =VLOOKUP(발송처리!V68,'상품DB(수정x)'!B:E,4,0) -> #N/A | G68: =발송처리!X68 -> 0 | I68: =발송처리!AW68 -> 0 | K68: =IF(LEFT(E68,1)="2","",IF(LEFT(E68,1)="4","",IF(Q68>=500000,"★증정★테이프20mx2",IF(Q68>=95000,"★증정★테이프20mx1","")))) -> #N/A | L68: =발송처리!AU68 -> 0 | M68: =발송처리!AP68 -> 0 | N68: =발송처리!AV68 -> 0 | O68: =발송처리!AR68 -> 0 | P68: =발송처리!K68 -> 0 | Q68: =발송처리!AC68 -> 0
... A772: =발송처리!A772 -> 0 | B772: =발송처리!M772 -> 0 | E772: =VLOOKUP(발송처리!V772,'상품DB(수정x)'!B:E,2,0) -> #N/A | F772: =VLOOKUP(발송처리!V772,'상품DB(수정x)'!B:E,4,0) -> #N/A | G772: =발송처리!X772 -> 0 | I772: =발송처리!AW772 -> 0 | K772: =IF(LEFT(E772,1)="2","",IF(LEFT(E772,1)="4","",IF(Q772>=500000,"★증정★테이프20mx2",IF(Q772>=95000,"★증정★테이프20mx1","")))) -> #N/A | L772: =발송처리!AU772 -> 0 | M772: =발송처리!AP772 -> 0 | N772: =발송처리!AV772 -> 0 | O772: =발송처리!AR772 -> 0 | P772: =발송처리!K772 -> 0 | Q772: =발송처리!AC772 -> 0

Sheet 송장화2
A1: 상품주문번호 | B1: 수취인명 | C1: 운임타입 | D1: 송장수량 | E1: 디자인 | F1: 길이 | G1: 수량 | H1: 디자인+수량 | I1: 배송메세지 | J1: 합포장 | K1: 비고 | L1: 주문하신분 핸드폰 | M1: 받는분 핸드폰 | N1: 우편번호 | O1: 받는분 주소 | P1: 주문자명 | Q1: 실제결제금액
A2: 2025121699509111 | B2: 김기민 | C2: 6000 | D2: 1 | E2: (110)15TPE딜라이트우드 | F2: 2m | G2: 1 | H2: =CONCATENATE(E2,F2,"x",G2) -> (110)15TPE딜라이트우드2mx1 | L2: 010-2914-9937 | M2: 010-2914-9937 | N2: 10811 | O2: 경기도 파주시 문산읍 통일로 1750 (문산읍, 문산어울림) 문산어울림 105동 501호 | P2: 김기민 | Q2: 32560
A3: 2025121553369521 | B3: 3-3이민수 | C3: 4500 | D3: 1 | E3: (70)17T마블아이보리 | F3: 4.5m | G3: 1 | H3: =CONCATENATE(E3,F3,"x",G3) -> (70)17T마블아이보리4.5mx1 | L3: 010-9924-5053 | M3: 010-9924-5053 | N3: 42793 | O3: 대구광역시 달서구 상화북로 159 (상인동, 산호아파트) 7동202호 | P3: 이민수 | Q3: 96300
A4: 2025121699647131 | B4: 이주현★ | C4: 19400 | D4: 1 | E4: (140)17T퓨어아이보리 | F4: 8m | G4: 1 | H4: =CONCATENATE(E4,F4,"x",G4) -> (140)17T퓨어아이보리8mx1 | I4: ★파손주의★문 앞에 놓아주세요 | K4: ★증정★테이프20mx1 | L4: 010-6412-7957 | M4: 010-6412-7957 | N4: 10562 | O4: 경기도 고양시 덕양구 원흥1로 31 (원흥동, 고양삼송엘에이치10단지아파트) 1004-502 | P4: 이주현 | Q4: 262080
A5: 2025121696405561 | B5: 전준하★ | C5: 19400 | D5: 1 | E5: (140)17T퓨어아이보리 | F5: 8m | G5: 1 | H5: =CONCATENATE(E5,F5,"x",G5) -> (140)17T퓨어아이보리8mx1 | I5: ★파손주의★물품 잘 확인해서 보내주세요. 배송시 문자주시고 문앞에 놓아주세요. 감사합니다. | K5: ★증정★테이프20mx1 | L5: 010-5153-1054 | M5: 010-5153-1054 | N5: 18405 | O5: 경기도 화성시 병점3로 117 (병점동, 안화동마을주공9단지) 901동 1605호 | P5: 전준하 | Q5: 262080
A6: 2025121695559201 | B6: 나병준 | C6: 12700 | D6: 1 | E6: 25T(퍼즐)아이보리(50) | G6: 6 | H6: =CONCATENATE(E6,F6,"x",G6) -> 25T(퍼즐)아이보리(50)x6 | L6: 010-9174-1121 | M6: 010-9174-1121 | N6: 16823 | O6: 경기도 용인시 수지구 손곡로 82 (동천동, 수진마을써니벨리아파트) 106동 506호 | P6: 나병준 | Q6: 106400
A7: 2025121594828291 | B7: 4-3나대남 | E7: ★판매★테이프20m | G7: 1 | H7: =CONCATENATE(E7,F7,"x",G7) -> ★판매★테이프20mx1 | I7: 배송 전 미리 연락해 주세요 | J7: 합 | L7: 010-8965-2389 | M7: 0502-3214-2132 | N7: 01014 | O7: 서울특별시 강북구 4.19로13길 9 (수유동, 우이블루빌) 402호 | P7: 나대남 | Q7: 7900
A8: 2025121594828281 | B8: 4-1나대남★ | C8: 12700 | D8: 1 | E8: (110)17T마블아이보리 | F8: 5.5m | G8: 1 | H8: =CONCATENATE(E8,F8,"x",G8) -> (110)17T마블아이보리5.5mx1 | I8: ★파손주의★ | L8: 010-8965-2389 | M8: 0502-3214-2132 | N8: 01014 | O8: 서울특별시 강북구 4.19로13길 9 (수유동, 우이블루빌) 402호 | P8: 나대남 | Q8: 151800
A9: 2025121594828271 | B9: 4-2나대남 | C9: 12100 | D9: 1 | E9: (110)17T마블아이보리 | F9: 5m | G9: 1 | H9: =CONCATENATE(E9,F9,"x",G9) -> (110)17T마블아이보리5mx1 | I9: 배송 전 미리 연락해 주세요 | K9: ★증정★테이프20mx3 | L9: 010-8965-2389 | M9: 0502-3214-2132 | N9: 01014 | O9: 서울특별시 강북구 4.19로13길 9 (수유동, 우이블루빌) 402호 | P9: 나대남 | Q9: 248400
A10: 2025121594828271 | B10: 4-3나대남 | C10: 12100 | D10: 1 | E10: (110)17T마블아이보리 | F10: 5m | G10: 1 | H10: =CONCATENATE(E10,F10,"x",G10) -> (110)17T마블아이보리5mx1 | I10: 배송 전 미리 연락해 주세요 | J10: 합 | L10: 010-8965-2389 | M10: 0502-3214-2132 | N10: 01014 | O10: 서울특별시 강북구 4.19로13길 9 (수유동, 우이블루빌) 402호 | P10: 나대남 | Q10: 248400
A11: 2025121594828261 | B11: 4-4나대남 | C11: 13800 | D11: 1 | E11: (120)17T마블아이보리 | F11: 3m | G11: 1 | H11: =CONCATENATE(E11,F11,"x",G11) -> (120)17T마블아이보리3mx1 | I11: 배송 전 미리 연락해 주세요 | J11: 합 | L11: 010-8965-2389 | M11: 0502-3214-2132 | N11: 01014 | O11: 서울특별시 강북구 4.19로13길 9 (수유동, 우이블루빌) 402호 | P11: 나대남 | Q11: 91800
A12: 2025121594828251 | B12: 4-4나대남 | E12: (120)17T마블아이보리 | F12: 2m | G12: 1 | H12: =CONCATENATE(E12,F12,"x",G12) -> (120)17T마블아이보리2mx1 | I12: 배송 전 미리 연락해 주세요 | J12: 합 | L12: 010-8965-2389 | M12: 0502-3214-2132 | N12: 01014 | O12: 서울특별시 강북구 4.19로13길 9 (수유동, 우이블루빌) 402호 | P12: 나대남 | Q12: 59200
A13: 2025121594230371 | B13: 최규철 | C13: 8600 | D13: 1 | E13: (140)6T소프트그레이 | F13: 2m | G13: 1 | H13: =CONCATENATE(E13,F13,"x",G13) -> (140)6T소프트그레이2mx1 | L13: 010-8823-9437 | M13: 010-8823-9437 | N13: 37107 | O13: 경상북도 상주시 이안면 양범안룡길 80 (이안면) 양범교회 | P13: 최규철 | Q13: 52800
A14: 2025121594072441 | B14: 한정우 | C14: 6900 | D14: 1 | E14: 플러스♥25T아이(100) | G14: 1 | H14: =CONCATENATE(E14,F14,"x",G14) -> 플러스♥25T아이(100)x1 | L14: 010-9524-9234 | M14: 010-9524-9234 | N14: 07520 | O14: 서울특별시 강서구 양천로 177 (마곡동, 가양하수처리장직원아파트) 2동 206호 | P14: 한정우 | Q14: 22800
A15: 2025121593854551 | B15: 2-1류춘렬 | C15: 12100 | D15: 1 | E15: (110)17T퓨어아이보리 | F15: 5m | G15: 1 | H15: =CONCATENATE(E15,F15,"x",G15) -> (110)17T퓨어아이보리5mx1 | K15: ★증정★테이프20mx1 | L15: 010-8736-8737 | M15: 010-8736-8737 | N15: 34049 | O15: 대전광역시 유성구 엑스포로 448 엑스포아파트 202동 1701호 | P15: 류춘렬 | Q15: 248400
A16: 2025121593854551 | B16: 2-2류춘렬 | C16: 12100 | D16: 1 | E16: (110)17T퓨어아이보리 | F16: 5m | G16: 1 | H16: =CONCATENATE(E16,F16,"x",G16) -> (110)17T퓨어아이보리5mx1 | L16: 010-8736-8737 | M16: 010-8736-8737 | N16: 34049 | O16: 대전광역시 유성구 엑스포로 448 엑스포아파트 202동 1701호 | P16: 류춘렬 | Q16: 248400
A17: 2025121591163141 | B17: 서혜린 | C17: 6900 | D17: 1 | E17: 25T(퍼즐)아이보리(50) | G17: 2 | H17: =CONCATENATE(E17,F17,"x",G17) -> 25T(퍼즐)아이보리(50)x2 | L17: 010-3959-9166 | M17: 010-3959-9166 | N17: 17066 | O17: 경기도 용인시 기흥구 기흥역로58번길 56 (구갈동, 기흥역 파크 푸르지오) 301동3302호 | P17: 서혜린 | Q17: 34720
A18: 2025121590839141 | B18: 최향 | C18: 8600 | D18: 1 | E18: (120)17T소프트그레이 | F18: 2m | G18: 1 | H18: =CONCATENATE(E18,F18,"x",G18) -> (120)17T소프트그레이2mx1 | L18: 010-5550-1258 | M18: 010-5550-1258 | N18: 11748 | O18: 경기도 의정부시 시민로 287 (신곡동) 이편한세상 신곡파크비스타 109동301호 | P18: 최향 | Q18: 55080
A19: 2025121590742721 | B19: 2-1이규원 | C19: 10700 | D19: 1 | E19: 25T(퍼즐)아이보리(100) | G19: 5 | H19: =CONCATENATE(E19,F19,"x",G19) -> 25T(퍼즐)아이보리(100)x5 | I19: 부재시 문앞에 놔주세용 | L19: 010-8919-4157 | M19: 010-8919-4157 | N19: 11941 | O19: 경기도 구리시 원수택로32번길 60 (수택동, 성경아파트) 3동 402호 | P19: 이규원 | Q19: 143200
A20: 2025121590742721 | B20: 2-2이규원 | C20: 10700 | D20: 1 | E20: 25T(퍼즐)아이보리(100) | G20: 3 | H20: =CONCATENATE(E20,F20,"x",G20) -> 25T(퍼즐)아이보리(100)x3 | I20: 부재시 문앞에 놔주세용 | J20: 합 | L20: 010-8919-4157 | M20: 010-8919-4157 | N20: 11941 | O20: 경기도 구리시 원수택로32번길 60 (수택동, 성경아파트) 3동 402호 | P20: 이규원 | Q20: 143200
A21: 2025121590742711 | B21: 2-2이규원 | E21: 25T(퍼즐)아이보리(50) | G21: 2 | H21: =CONCATENATE(E21,F21,"x",G21) -> 25T(퍼즐)아이보리(50)x2 | I21: 부재시 문앞에 놔주세용 | J21: 합 | L21: 010-8919-4157 | M21: 010-8919-4157 | N21: 11941 | O21: 경기도 구리시 원수택로32번길 60 (수택동, 성경아파트) 3동 402호 | P21: 이규원 | Q21: 34800
A22: 2025121590061171 | B22: 2-1김예찬 | C22: 10700 | D22: 1 | E22: 25T(퍼즐)아이보리(100) | G22: 5 | H22: =CONCATENATE(E22,F22,"x",G22) -> 25T(퍼즐)아이보리(100)x5 | L22: 010-6886-3860 | M22: 010-6886-3860 | N22: 34899 | O22: 대전광역시 중구 계백로1615번길 34 (유천동, 현대아파트) 113동 1407호 | P22: 김예찬 | Q22: 161100
A23: 2025121590061171 | B23: 2-2김예찬 | C23: 8600 | D23: 1 | E23: 25T(퍼즐)아이보리(100) | G23: 4 | H23: =CONCATENATE(E23,F23,"x",G23) -> 25T(퍼즐)아이보리(100)x4 | L23: 010-6886-3860 | M23: 010-6886-3860 | N23: 34899 | O23: 대전광역시 중구 계백로1615번길 34 (유천동, 현대아파트) 113동 1407호 | P23: 김예찬 | Q23: 161100
A24: 2025121588680721 | B24: 2-1최영미 | C24: 8600 | D24: 1 | E24: 25T(퍼즐)아이보리(100) | G24: 4 | H24: =CONCATENATE(E24,F24,"x",G24) -> 25T(퍼즐)아이보리(100)x4 | L24: 010-5574-4480 | M24: 010-5574-4480 | N24: 10931 | O24: 경기도 파주시 시청로 85 (아동동, 신안실크밸리2차 아파트) 206동303호 | P24: 최영미 | Q24: 141200
A25: 2025121588680721 | B25: 2-2최영미 | C25: 8600 | D25: 1 | E25: 25T(퍼즐)아이보리(100) | G25: 4 | H25: =CONCATENATE(E25,F25,"x",G25) -> 25T(퍼즐)아이보리(100)x4 | L25: 010-5574-4480 | M25: 010-5574-4480 | N25: 10931 | O25: 경기도 파주시 시청로 85 (아동동, 신안실크밸리2차 아파트) 206동303호 | P25: 최영미 | Q25: 141200
